Workbook
Name 安规: 数据源!$L$2:$L$24
Name 包装: 数据源!$H$2:$H$24
Name 不涉及: 数据源!$AL$2
Name 否: 数据源!$AK$2:$AK$12
Name 功能: 数据源!$K$2:$K$24
Name 计划采购部: 数据源!$AC$2:$AC$6
Name 技术质量部: 数据源!$AD$2:$AD$6
Name 内部: 数据源!$J$2:$J$24
Name 其它: 数据源!$N$2:$N$24
Name 试产: 数据源!$E$2:$E$6
Name 是: 数据源!$AJ$2:$AJ$7
Name 外观: 数据源!$I$2:$I$24
Name 宜胜照明1: 数据源!$Z$2:$Z$6
Name 宜胜照明2: 数据源!$AA$2:$AA$6
Name 宜胜照明3: 数据源!$AB$2:$AB$6

Sheet 宜胜客诉台账
A1: 发生时间 | B1: 年 | C1: 月 | D1: 周 | E1: 订单号 | F1: 产品型号 | G1: 客户 | H1: 事业部 | I1: 业务 | J1: 产品 | K1: CQE | L1: 问题描述 | M1: 订单数量 | N1: 客诉数量 | O1: 不良占比 | P1: 问题来源 | Q1: 问题类别 | R1: 原因分析 | S1: 原因类别 | T1: 临时措施 | U1: 长期措施 | V1: 是否根本解 | W1: 措施类型 | X1: 责任部门 | Y1: 二级部门3 | Z1: 计划完成时间 | AA1: 实际完成时间 | AB1: 状态 | AC1: 跟进人 | AD1: 计划完成年 | AE1: 计划完成月 | AF1: 计划完成周
A2: 45469 | B2: =IF(A2="","",YEAR(A2)) -> 2024 | C2: =IF(A2="","",TEXT(A2,"m")) -> 6 | D2: =IF(A2="","","W"&WEEKNUM(A2,2)) -> W26 | E2: Y23P1108 | F2: AL5005-9W | G2: 澳大利亚1541 | H2: 宜胜照明2 | I2: 徐碧琳 | J2: 彭弼坤 | K2: 吴军 | L2: 测试点亮过程中，灯不亮，通电1分钟左右冒烟 | O2: =IFERROR(N2/M2,"") | P2: 售后客诉 | Q2: 功能 | R2: 1.通过客户提供信息，进行失效模式复现，当灯板端子脱焊松动通电后，1分20秒左右产品冒浓烟，功率升高至10-25W，2分40秒后烟雾逐渐消失，3分钟后所有现象消失；检查灯板，电容尾部有鼓包、发黑现象，电容下方有漏液，其他无异常；与客户提供视频及图片完全一致； 2.抽取5PCS灯板进行焊点拉力测试，测试结果均≥40N,远远高一般标准≥10N,排除产品批量焊接不良可能性； 3.经过以上排查分析，此次问题是由于灯板端子虚焊松动，导致上电空载，电容电解液分解产生浓烟，完全分解后浓烟消失，电路断开，排除后续可能造成失火现象等不良影响，且筒灯壳体为阻燃材质； 4.端子虚焊流出原因： ①维修品未经老化测试流入包装； ②PCB及元器件受潮； ③印刷锡膏开盖后未及时使用完毕； ④印刷钢网未及时清洗； | S2: 电子设计 | T2: 1.排查现有库存以及订单情况，现有客户订单Y24P0507-1，订单量20000PCS； 2.暂停生产，待排查处理结果； 3.根据客户提供信息，进行失效模式复现； | U2: 1.不良品红色标贴标识，维修品分批统一老化测试; 2.SMT车间温湿度接近管控范围增加预警机制; 3.锡膏使用采取先进先出，保证开盖锡膏24小时内使用完; 4.换线停线超过1小时按工艺要求清洁钢网 | V2: 否 | W2: 工艺优化 | X2: 宜胜照明2 | Y2: 生产二 | Z2: 45469 | AA2: 45469 | AB2: =IF(A2="","",_xlfn.IFS(AND(Z2=0,AA2=0),"未回复",AND(AA2<>0,Z2=0),"报错",AND(Z2>=NOW(),Z2<>0,AA2=0),"正常进行中",AND(AA2<>0,Z2>=AA2),"按时关闭",AND(Z2<>0,Z2<=AA2),"延期关闭",AND(AA2=0,Z2<NOW()),"延期未关闭")) -> 按时关闭 | AC2: 赵纯杰 | AD2: =IF(Z2="","",YEAR(Z2)) -> 2024 | AE2: =IF(Z2="","",TEXT(Z2,"m")) -> 6 | AF2: =IF(Z2="","","W"&WEEKNUM(Z2,2)) -> W26
A3: 45446 | B3: =IF(A3="","",YEAR(A3)) -> 2024 | C3: =IF(A3="","",TEXT(A3,"m")) -> 6 | D3: =IF(A3="","","W"&WEEKNUM(A3,2)) -> W23 | E3: D24A003 | F3: LC1201C-7W2-G7-低漏光 | G3: 捷克081 | H3: 宜胜照明1 | I3: 金凤燕 | J3: 谢彭沛 | K3: 李宁 | L3: 4000K的漏光严重（见附件），客户索赔金额276美金。 | O3: =IFERROR(N3/M3,"") | P3: 售后客诉 | Q3: 外观 | R3: 事情缘由：客户下单产品为低漏光版本，壳体为老模具库存消耗完后，壳体涉及停产，剩下2000数量，需验证壳体才能做大货，壳体验证时有进行照片拍摄，漏光效果不明显，就通知进行安排做货，验证方案时效果如下 问题暴漏：验证时验证效果不充分，壳体涉及停产未及时进行产品替代。 后续处理：1.充分验证壳体漏光效果，寻找替代壳体。2：涉及停产及时进行替代。3：需找到壳体给客户重新寄样进行确认。 补充：此订单下单日期为20240112，刚实行报价制度阶段，业务已进行利润给到工业端，按照当时下单流程节点，此订单业务所加的利润在宜胜端口 后面收到客诉通知再次进行验证，发现确实存在漏光，再次测试效果如下 | S3: 来料不良 | T3: 这个订单要求低漏光的壳体材料，原材料工厂有4000个，宇兴先用这批做了3000只3000K和1000只4000K。 因为原材料工厂后面不做这个低漏光的壳体了，后面的2000个壳体找了另一家新工厂做的。 产品端针对新供方物料有打样确认验证过，但未发现有漏光问题。 核对当时的留样，发现该产品只有在暗光处、位置较低处，漏光才会较为明显，对比客户反馈的图片，问题一致。 结论： 产品经理在更换新供方之后，有打样验证的动作，但未跟客户进行确认。导致双方判定标准有差异 | U3: 后续类似情况，需与客户端做确认，保证标准理解一致 | V3: 否 | W3: 纠错 | X3: 宜胜照明1 | Y3: 研发六 | Z3: 45455 | AA3: 45455 | AB3: =IF(A3="","",_xlfn.IFS(AND(Z3=0,AA3=0),"未回复",AND(AA3<>0,Z3=0),"报错",AND(Z3>=NOW(),Z3<>0,AA3=0),"正常进行中",AND(AA3<>0,Z3>=AA3),"按时关闭",AND(Z3<>0,Z3<=AA3),"延期关闭",AND(AA3=0,Z3<NOW()),"延期未关闭")) -> 按时关闭 | AC3: 杨高照 | AD3: =IF(Z3="","",YEAR(Z3)) -> 2024 | AE3: =IF(Z3="","",TEXT(Z3,"m")) -> 6 | AF3: =IF(Z3="","","W"&WEEKNUM(Z3,2)) -> W24
A4: 45447 | B4: =IF(A4="","",YEAR(A4)) -> 2024 | C4: =IF(A4="","",TEXT(A4,"m")) -> 6 | D4: =IF(A4="","","W"&WEEKNUM(A4,2)) -> W23 | L4: 投光灯进水 | O4: =IFERROR(N4/M4,"") | P4: 售后客诉 | Q4: 功能 | S4: 其它 | V4: 是 | W4: 其它 | X4: 宜胜照明3 | Z4: 45447 | AA4: 45447 | AB4: =IF(A4="","",_xlfn.IFS(AND(Z4=0,AA4=0),"未回复",AND(AA4<>0,Z4=0),"报错",AND(Z4>=NOW(),Z4<>0,AA4=0),"正常进行中",AND(AA4<>0,Z4>=AA4),"按时关闭",AND(Z4<>0,Z4<=AA4),"延期关闭",AND(AA4=0,Z4<NOW()),"延期未关闭")) -> 按时关闭 | AC4: 杨高照 | AD4: =IF(Z4="","",YEAR(Z4)) -> 2024 | AE4: =IF(Z4="","",TEXT(Z4,"m")) -> 6 | AF4: =IF(Z4="","","W"&WEEKNUM(Z4,2)) -> W23
A5: 45488 | B5: =IF(A5="","",YEAR(A5)) -> 2024 | C5: =IF(A5="","",TEXT(A5,"m")) -> 7 | D5: =IF(A5="","","W"&WEEKNUM(A5,2)) -> W29 | L5: 收到客户反馈，订单：A123S233 65WT灯灯杯摇晃内部有一些异响，有一些摇晃没有异响（正常品为没有异响），经分析PCB板和灯杯卡槽之间有的没有点胶。有的胶量点少了，导致PCB板脱落，故T灯出现摇晃异响现象； | O5: =IFERROR(N5/M5,"") | P5: 售后客诉 | Q5: 内部 | R5: 1、产生原因： 生产过程中，先点胶再卡PCB板，有个别灯杯卡槽在没有点胶的情况下，插上了控制板，还有个别灯杯卡槽位置胶量点少了，也插上控制板了。 2、流出原因： 由于该型号产品是半自动产线生产的，外观检查时会通过“来回晃动听声音”的方式来判断灯体内部是否固定好控制板，因为板子插在卡槽内，部分没有听出响动，判断合格，初步分析为工人在中午下班时间，有个别产品在半自动线上，未完成作业，上班时，打胶后产品胶干了导致不良品流出。 | S5: 过程工艺 | T5: 1.库存排查：瑞亚仓库数量3000PCS，将仓库货物进行返工。开箱进行摇晃后在点亮测试，3000台未发现不良品。 | U5: 1.更改作业流程，先卡PCB板，在点胶，确保每个灯杯的卡槽内有足够的胶量。 生产工单，备注点胶作业。 2.SOP增加工位检查点胶作业流程。 1.车间生产前给员工培训，按SOP流程作业，下班前5分钟清空生产线未完成半成品。 2.品质巡检过程中检查该工序，生产是否落实下去。下班前清空生产线半成品。 | V5: 否 | W5: 工艺优化 | X5: 宜胜照明1 | Y5: 研发六 | Z5: 45496 | AA5: 45496 | AB5: =IF(A5="","",_xlfn.IFS(AND(Z5=0,AA5=0),"未回复",AND(AA5<>0,Z5=0),"报错",AND(Z5>=NOW(),Z5<>0,AA5=0),"正常进行中",AND(AA5<>0,Z5>=AA5),"按时关闭",AND(Z5<>0,Z5<=AA5),"延期关闭",AND(AA5=0,Z5<NOW()),"延期未关闭")) -> 按时关闭 | AC5: 李俊林 | AD5: =IF(Z5="","",YEAR(Z5)) -> 2024 | AE5: =IF(Z5="","",TEXT(Z5,"m")) -> 7 | AF5: =IF(Z5="","","W"&WEEKNUM(Z5,2)) -> W30
A6: 45477 | B6: =IF(A6="","",YEAR(A6)) -> 2024 | C6: =IF(A6="","",TEXT(A6,"m")) -> 7 | D6: =IF(A6="","","W"&WEEKNUM(A6,2)) -> W27 | L6: 瑞士070面板灯夹膜 | O6: =IFERROR(N6/M6,"") | P6: 售后客诉 | Q6: 内部 | S6: 人员作业 | V6: 是 | W6: 防呆防错 | X6: 宜胜照明2 | Z6: 45478 | AB6: =IF(A6="","",_xlfn.IFS(AND(Z6=0,AA6=0),"未回复",AND(AA6<>0,Z6=0),"报错",AND(Z6>=NOW(),Z6<>0,AA6=0),"正常进行中",AND(AA6<>0,Z6>=AA6),"按时关闭",AND(Z6<>0,Z6<=AA6),"延期关闭",AND(AA6=0,Z6<NOW()),"延期未关闭")) -> 延期未关闭 | AC6: 杨高照 | AD6: =IF(Z6="","",YEAR(Z6)) -> 2024 | AE6: =IF(Z6="","",TEXT(Z6,"m")) -> 7 | AF6: =IF(Z6="","","W"&WEEKNUM(Z6,2)) -> W27
A7: 45467 | B7: =IF(A7="","",YEAR(A7)) -> 2024 | C7: =IF(A7="","",TEXT(A7,"m")) -> 6 | D7: =IF(A7="","","W"&WEEKNUM(A7,2)) -> W26 | E7: Y24D0307 | F7: AL2017 | G7: 菲律宾1579-1 | H7: 宜胜照明2 | J7: 彭弼坤 | K7: 周利军 | L7: 扭簧护套掉色 | O7: =IFERROR(N7/M7,"") | P7: 售后客诉 | Q7: 外观 | R7: PVC材质，蓝色护套与绿色护套高温高湿验证，绿色护套脱色现象 | S7: 结构设计 | V7: 否 | AB7: =IF(A7="","",_xlfn.IFS(AND(Z7=0,AA7=0),"未回复",AND(AA7<>0,Z7=0),"报错",AND(Z7>=NOW(),Z7<>0,AA7=0),"正常进行中",AND(AA7<>0,Z7>=AA7),"按时关闭",AND(Z7<>0,Z7<=AA7),"延期关闭",AND(AA7=0,Z7<NOW()),"延期未关闭")) -> 未回复 | AC7: 赵纯杰 | AD7: =IF(Z7="","",YEAR(Z7)) | AE7: =IF(Z7="","",TEXT(Z7,"m")) | AF7: =IF(Z7="","","W"&WEEKNUM(Z7,2))
A8: 45471 | B8: =IF(A8="","",YEAR(A8)) -> 2024 | C8: =IF(A8="","",TEXT(A8,"m")) -> 6 | D8: =IF(A8="","","W"&WEEKNUM(A8,2)) -> W26 | E8: R24D0207 | F8: LB1163E1-9W2/LB211-8W | L8: LB1163E1-9W2漏装1箱 LB211-8W漏装30箱 | O8: =IFERROR(N8/M8,"") | P8: 售后客诉 | Q8: 其它 | S8: 人员作业 | V8: 否 | W8: 纠错 | AB8: =IF(A8="","",_xlfn.IFS(AND(Z8=0,AA8=0),"未回复",AND(AA8<>0,Z8=0),"报错",AND(Z8>=NOW(),Z8<>0,AA8=0),"正常进行中",AND(AA8<>0,Z8>=AA8),"按时关闭",AND(Z8<>0,Z8<=AA8),"延期关闭",AND(AA8=0,Z8<NOW()),"延期未关闭")) -> 未回复 | AC8: 杨高照 | AD8: =IF(Z8="","",YEAR(Z8)) | AE8: =IF(Z8="","",TEXT(Z8,"m")) | AF8: =IF(Z8="","","W"&WEEKNUM(Z8,2))
A9: 45496 | B9: =IF(A9="","",YEAR(A9)) -> 2024 | C9: =IF(A9="","",TEXT(A9,"m")) -> 7 | D9: =IF(A9="","","W"&WEEKNUM(A9,2)) -> W30 | E9: M24L009-1 | F9: HL132 | G9: 巴西724 | H9: 宜胜照明3 | J9: 邱奇 | K9: 丁亚双 | L9: 混装1箱其他客户产品 | O9: =IFERROR(N9/M9,"") | P9: 售后客诉 | Q9: 其它 | R9: 混料 | S9: 人员作业 | T9: 库存全检返工 | U9: 1.备品配件损耗全部降低（已经执行）. 2.备品改为易损耗物料有备品不会是整套物料有备品（不会多做齐套产品）. 3.车间安排专人入库入库前数量核对入库后与仓管核对数量. 4.车间对班组长以及员工宣导培训. 5.针对同产品不同客户计划排产分开排产. 6.多生产产品车间统一放置与大货分开. | V9: 否 | W9: 纠错 | X9: 宜胜照明3 | Z9: 45498 | AA9: 45498 | AB9: =IF(A9="","",_xlfn.IFS(AND(Z9=0,AA9=0),"未回复",AND(AA9<>0,Z9=0),"报错",AND(Z9>=NOW(),Z9<>0,AA9=0),"正常进行中",AND(AA9<>0,Z9>=AA9),"按时关闭",AND(Z9<>0,Z9<=AA9),"延期关闭",AND(AA9=0,Z9<NOW()),"延期未关闭")) -> 按时关闭 | AC9: 赵纯杰 | AD9: =IF(Z9="","",YEAR(Z9)) -> 2024 | AE9: =IF(Z9="","",TEXT(Z9,"m")) -> 7 | AF9: =IF(Z9="","","W"&WEEKNUM(Z9,2)) -> W30
A10: 45499 | B10: =IF(A10="","",YEAR(A10)) -> 2024 | C10: =IF(A10="","",TEXT(A10,"m")) -> 7 | D10: =IF(A10="","","W"&WEEKNUM(A10,2)) -> W30 | E10: Z23T013 | F10: LG158-50W-W-G3 | G10: 埃及442 | H10: 宜胜照明3 | J10: 陈中平协助 | K10: 李冬雪 | L10: 客户反馈产品组装后测试点亮1个小时内出现闪灯与不亮 | O10: =IFERROR(N10/M10,"") | P10: 售后客诉 | Q10: 功能 | R10: 1. 发生原因： - 电源板 C4 电容贴错。BOM 要求为 22PF 的电容，实际为 220PF，造成空载电压 130，超过电解电容 100V 耐压，导致电容击穿。 2. 流出原因： - 整个生产批次均未执行有效的首件检验，料号、BOM信息未核对正确，导致错误未被及时发现（电容规格0805 220 50V误认为220PF电容，实际0805 220 50V是22PF电容。 - 本订单散件发货，客户组装，但大货生产时未进行成品组装老化及功能测试，未对成品的性能做管控 | S10: 人员作业 | T10: 重新生产一批电源板补发客户 | U10: 永久纠正措施：1. 对负责该生产批次的作业人员进行重新培训和考核，确保其熟练掌握正确的贴片操作和 BOM 核对流程，明确操作规范和质量要求，并定期考核。 2. 优化生产流程，在贴片环节前增加物料二次核对步骤，由专人负责； 3. 优化质量管控流程，完善首件检验制度，明确检验标准和责任人员，首件检验结果需记录并签字确认，合理增加关键部件的抽检比例和频率； 预防措施：1. 完善物料管理制度 - 建立严格的物料入库检验流程，对每一批次的物料进行规格、型号、参数等方面的抽检，确保物料符合要求。 - 优化物料存储环境，按照不同规格和型号分类存放，并做好明确标识。 2. 强化生产过程中的检验环节 - 制定详细的生产流程检验标准和操作指南，明确每个工序的检验项目和责任人。 3. 持续培训与教育 - 定期组织作业人员参加技能培训和质量意识教育活动，分享常见的质量问题案例及解决方法，提高员工的质量意识和操作技能。 4. 优化订单管理 - 对于散件发货的订单，在生产过程中增加模拟组装、老化及功能测试环节，确保产品性能符合要求后再发货。 5. 加强监督与审核 - 成立专门的质量监督小组，定期对生产过程和产品质量进行检查和审核，对不符合质量要求的行为进行及时纠正和处罚。 | V10: 是 | W10: 防呆防错 | X10: 宜胜照明3 | Z10: 45503 | AA10: 45503 | AB10: =IF(A10="","",_xlfn.IFS(AND(Z10=0,AA10=0),"未回复",AND(AA10<>0,Z10=0),"报错",AND(Z10>=NOW(),Z10<>0,AA10=0),"正常进行中",AND(AA10<>0,Z10>=AA10),"按时关闭",AND(Z10<>0,Z10<=AA10),"延期关闭",AND(AA10=0,Z10<NOW()),"延期未关闭")) -> 按时关闭 | AC10: 赵纯杰 | AD10: =IF(Z10="","",YEAR(Z10)) -> 2024 | AE10: =IF(Z10="","",TEXT(Z10,"m")) -> 7 | AF10: =IF(Z10="","","W"&WEEKNUM(Z10,2)) -> W31
A11: 45512 | B11: =IF(A11="","",YEAR(A11)) -> 2024 | C11: =IF(A11="","",TEXT(A11,"m")) -> 8 | D11: =IF(A11="","","W"&WEEKNUM(A11,2)) -> W32 | E11: P24V001-1 | F11: LG172L-30W2-俄罗斯482 | G11: 俄罗斯482 | H11: 宜胜照明3 | I11: 黄亚琳 | J11: 王燕赟 | K11: 周利军 | L11: 1.50W, 70W, 100W 掉功率 2. 所有产品电线不阻燃 客户索赔29034.72元（4021.43美元） | M11: 40988 | N11: 40988 | O11: =IFERROR(N11/M11,"") -> 1 | P11: 售后客诉 | Q11: 功能 | R11: 1.经分析本批次产品掉功率，锁定原因为导热硅脂导热系数不合格，要求1.5W/mk，实测1.2076W/mk 2.电源线不阻燃为设计原因，未使用阻燃材料 | S11: 来料不良 | T11: 1.本批次产品客户让步接收，后续继续跟进，如有异常及时提供技术支持和解决方案 2.立即启动对后续产品的预防措施，防止类似问题再次发生 | U11: 1.更换导热系数符合标准(1.5W/hk)的导热硅脂，加强原材料检验环节，确保导热硅脂质量 ； 2.电源线全部更换为阻燃材料，并建立严格的采购标准和检验流程； 3.完善检验规范，原检验标准“在额定电压条件下测试功率”更改为“在额定电压下持续运行20min，过程中LED光源功率应在标准值以内”； | V11: 是 | W11: 设计变更-预防 | X11: 宜胜照明3 | Y11: 研发一 | Z11: 45513 | AA11: 45513 | AB11: =IF(A11="","",_xlfn.IFS(AND(Z11=0,AA11=0),"未回复",AND(AA11<>0,Z11=0),"报错",AND(Z11>=NOW(),Z11<>0,AA11=0),"正常进行中",AND(AA11<>0,Z11>=AA11),"按时关闭",AND(Z11<>0,Z11<=AA11),"延期关闭",AND(AA11=0,Z11<NOW()),"延期未关闭")) -> 按时关闭 | AC11: 赵纯杰 | AD11: =IF(Z11="","",YEAR(Z11)) -> 2024 | AE11: =IF(Z11="","",TEXT(Z11,"m")) -> 8 | AF11: =IF(Z11="","","W"&WEEKNUM(Z11,2)) -> W32
A12: 45519 | B12: =IF(A12="","",YEAR(A12)) -> 2024 | C12: =IF(A12="","",TEXT(A12,"m")) -> 8 | D12: =IF(A12="","","W"&WEEKNUM(A12,2)) -> W33 | E12: T23S0620 （太阳能灯） | F12: F-WL106-10W | G12: 匈牙利087 | H12: 宜胜照明2 | I12: 陈晨怡 | J12: 周伟慧 | K12: 周利军 | L12: 8月初开始，客户陆续收到终端店铺的退货，主要问题在于灯头断裂，无法使用，目前没有可以维修的办法，只能报废处理。 8月7号开始，客户开始现有库存的全检工作。8月13号出全检结果，目前全检出来的不良数量200个。比例40% | M12: 504 | N12: 200 | O12: =IFERROR(N12/M12,"") -> 0.3968254 | P12: 售后客诉 | Q12: 功能 | R12: 1）螺丝打的比较紧，扭力大 2）运输过程中，横向收到冲击 | S12: 结构设计 | T12: 最终与客户沟通协商补货给他，本月畅想重新下单T24P037-1补货给客户，成本预计11536RMB | U12: 优化内部结构，中间连接处由直角改为圆角，使得进料更加连贯，同步增加塑料件的壁厚，使得连接处的受力面积增加，分散不同方向上的冲击力，让内部结构更加稳定；同时加厚了下方台阶（打螺丝的位置），对螺丝固定时起到更好的支撑 | V12: 是 | W12: 设计变更-预防 | X12: 其它事业部 | AB12: =IF(A12="","",_xlfn.IFS(AND(Z12=0,AA12=0),"未回复",AND(AA12<>0,Z12=0),"报错",AND(Z12>=NOW(),Z12<>0,AA12=0),"正常进行中",AND(AA12<>0,Z12>=AA12),"按时关闭",AND(Z12<>0,Z12<=AA12),"延期关闭",AND(AA12=0,Z12<NOW()),"延期未关闭")) -> 未回复 | AD12: =IF(Z12="","",YEAR(Z12)) | AE12: =IF(Z12="","",TEXT(Z12,"m")) | AF12: =IF(Z12="","","W"&WEEKNUM(Z12,2))
A13: 45519 | B13: =IF(A13="","",YEAR(A13)) -> 2024 | C13: =IF(A13="","",TEXT(A13,"m")) -> 8 | D13: =IF(A13="","","W"&WEEKNUM(A13,2)) -> W33 | E13: S21K008 | F13: Z2-LG502-10W | G13: 德国588 | H13: 宜胜照明2 | I13: 施月紫 | J13: 王燕赟 | K13: 周利军 | L13: 21K008订单2022年出货3000pcs工作灯，2024年1月发生客诉，产品塑料件开裂，比例很高。 客户要求全额赔偿；经协商后同意按50%货值给赔偿款，同时由我司免费赔货同等数量产品给客户替换。 而赔货产品不再另做大货，直接用T23U019此票订单遗留库存产品来出 | M13: 3000 | N13: 330 | O13: =IFERROR(N13/M13,"") -> 0.11 | P13: 售后客诉 | Q13: 外观 | R13: 1.塑料件供应商在生产过程中工艺控制不稳定，导致PC材料的强度、韧性等性能下降 2.注塑过程中工艺参数设置不合理，如温度、压力、冷却时间等，导致内应力残留 3.产品设计存在壁厚不均，在使用过程中容易产生应力集中，增加开裂风险 4.缺乏有效的加强结构设计，无法有效分散外力作用 | S13: 结构设计 | T13: 经协商后同意按50%货值给赔偿款，同时由我司免费赔货同等数量产品给客户替换。 而赔货产品不再另做大货，直接用T23U019此票订单遗留库存产 | U13: 1.与原材料供应商深入沟通，要求其加强生产过程质量控制，确保材料稳定性； 2.控制储存环境如温度。湿度，阳光直射等，避免因环境因素而导致性能下降； 3.设计应考虑壁厚分布，减少应力集中； 4.增加合理的加强结构，提高产品的整体强度和抗外力能力 | V13: 是 | W13: 纠错 | X13: 宜胜照明2 | Y13: 研发九 | Z13: 45521 | AA13: 45521 | AB13: =IF(A13="","",_xlfn.IFS(AND(Z13=0,AA13=0),"未回复",AND(AA13<>0,Z13=0),"报错",AND(Z13>=NOW(),Z13<>0,AA13=0),"正常进行中",AND(AA13<>0,Z13>=AA13),"按时关闭",AND(Z13<>0,Z13<=AA13),"延期关闭",AND(AA13=0,Z13<NOW()),"延期未关闭")) -> 按时关闭 | AC13: 赵纯杰 | AD13: =IF(Z13="","",YEAR(Z13)) -> 2024 | AE13: =IF(Z13="","",TEXT(Z13,"m")) -> 8 | AF13: =IF(Z13="","","W"&WEEKNUM(Z13,2)) -> W33
A14: 45512 | B14: =IF(A14="","",YEAR(A14)) -> 2024 | C14: =IF(A14="","",TEXT(A14,"m")) -> 8 | D14: =IF(A14="","","W"&WEEKNUM(A14,2)) -> W32 | E14: T24X003 | F14: ST-LR432-4WX5IC3-0612-G2-3M | G14: 德国793 | H14: 宜胜照明2 | I14: 姚优静 | J14: 屠磊 | K14: 周利军 | L14: 订单号：T24X003 产品：智能霓虹灯带 数量：16700pcs 订单金额：828821人民币 此订单为德国Aldi商超订单，下单前已明确产品需要符合客户的化学测试要求。 工厂提供的产前样化学测试没有问题，且保证大货品质跟产前样保持一致。 但是在验货阶段，大货抽样寄到德国测试之后发现化学不过，面临整单取消的风险。 经业务与供方核实后，发现大货确实存在污染，导致测试不过。 后经业务与客户沟通，最终成功说服终端让步接受，但是需要缴纳5000美元的罚金； 除此之外，整个订单过程中还产生679.09美元的重测费用，客户向我们索赔共计5679.09美元。 该笔索赔费用全部由供方承担 | M14: 16700 | N14: 16700 | O14: =IFERROR(N14/M14,"") -> 1 | P14: 售后客诉 | Q14: 安规 | R14: 对原材料以及贴片半成品进行检测排查，测试结果OK，灯条包皮后拿去测试，结果NG，锁定问题原因是包外皮机器之前生产过非ROSH要求的产品，使用了非环保材料，而水槽没有定期清洗导致。 | S14: 过程工艺 | T14: 1、设立环保产品专用包外皮机器，单独分开 2、料筒和材料区域单独分开 3、水槽做货前清洗。 2.立即启动对后续产品的预防措施，防止类似问题再次发生 | U14: 1.胶料材料商环保胶料独立车间生产 2.来料环保材料独立位置堆放 3.环保机器独立使用 | V14: 否 | W14: 供应商改善 | X14: 宜胜照明2 | Y14: 研发五 | Z14: 45519 | AA14: 45519 | AB14: =IF(A14="","",_xlfn.IFS(AND(Z14=0,AA14=0),"未回复",AND(AA14<>0,Z14=0),"报错",AND(Z14>=NOW(),Z14<>0,AA14=0),"正常进行中",AND(AA14<>0,Z14>=AA14),"按时关闭",AND(Z14<>0,Z14<=AA14),"延期关闭",AND(AA14=0,Z14<NOW()),"延期未关闭")) -> 按时关闭 | AC14: 赵纯杰 | AD14: =IF(Z14="","",YEAR(Z14)) -> 2024 | AE14: =IF(Z14="","",TEXT(Z14,"m")) -> 8 | AF14: =IF(Z14="","","W"&WEEKNUM(Z14,2)) -> W33
A15: 45535 | B15: =IF(A15="","",YEAR(A15)) -> 2024 | C15: =IF(A15="","",TEXT(A15,"m")) -> 8 | D15: =IF(A15="","","W"&WEEKNUM(A15,2)) -> W35 | E15: M24H005 | F15: ST-WS1002 9-2300W3- WFT-03-G1 | G15: 巴西527 | H15: 宜胜照明1 | I15: 徐赢意 | J15: 赖长金 | K15: 丁亚双 | L15: 单插黑色玻璃破损 | M15: 520 | N15: 520 | O15: =IFERROR(N15/M15,"") -> 1 | P15: 售后客诉 | Q15: 外观 | R15: 针对产品玻璃面板不良，排查因项目首次生产新工人未培训作业，导致工人未区分玻璃方向。将玻璃方向装反。 返工过程中玻璃面板已经打胶固定，工人使用工具对四个角撬开，造成玻璃面板损伤。 | S15: 过程工艺 | T15: 将已经完成打胶玻璃300台进行挑选返工，挑选出187台，拆开玻璃进行返工作业。 | U15: 1、此问题为首次生产导致。后续订单已经更改作业流程。2、将后续订单:M24H033进行排查，已排除此问题再次发生。首件确认合格 (生产、工业、品质）签字确认，大货上线生产。 3、玻璃破损问题已经要求作业人员规范作业。以及外观检验对比图。 | V15: 否 | W15: 流程优化 | X15: 宜胜照明1 | Y15: 生产一 | Z15: 45538 | AA15: 45538 | AB15: =IF(A15="","",_xlfn.IFS(AND(Z15=0,AA15=0),"未回复",AND(AA15<>0,Z15=0),"报错",AND(Z15>=NOW(),Z15<>0,AA15=0),"正常进行中",AND(AA15<>0,Z15>=AA15),"按时关闭",AND(Z15<>0,Z15<=AA15),"延期关闭",AND(AA15=0,Z15<NOW()),"延期未关闭")) -> 按时关闭 | AC15: 李俊林 | AD15: =IF(Z15="","",YEAR(Z15)) -> 2024 | AE15: =IF(Z15="","",TEXT(Z15,"m")) -> 9 | AF15: =IF(Z15="","","W"&WEEKNUM(Z15,2)) -> W36
A16: 45537 | B16: =IF(A16="","",YEAR(A16)) -> 2024 | C16: =IF(A16="","",TEXT(A16,"m")) -> 9 | D16: =IF(A16="","","W"&WEEKNUM(A16,2)) -> W36 | E16: A124S057+080 | F16: LC1101E-5 .5W2-G2-1 796 | G16: 郎德万斯-俄罗斯 | H16: 宜胜照明1 | I16: 张美娟 | K16: 王超 | L16: 订单A124S057+080大货客户已收到，但客户收到货后发现大货有异常现象： 1. 空彩盒（无产品） | M16: / | N16: / | O16: / | P16: 售后客诉 | Q16: 包装 | R16: 因为无法查询问题，已转内部报告回复 | S16: 人员作业 | X16: 其它事业部 | Y16: 供方管理组 | Z16: 45550 | AA16: 45550 | AB16: =IF(A16="","",_xlfn.IFS(AND(Z16=0,AA16=0),"未回复",AND(AA16<>0,Z16=0),"报错",AND(Z16>=NOW(),Z16<>0,AA16=0),"正常进行中",AND(AA16<>0,Z16>=AA16),"按时关闭",AND(Z16<>0,Z16<=AA16),"延期关闭",AND(AA16=0,Z16<NOW()),"延期未关闭")) -> 按时关闭 | AC16: 李俊林 | AD16: =IF(Z16="","",YEAR(Z16)) -> 2024 | AE16: =IF(Z16="","",TEXT(Z16,"m")) -> 9 | AF16: =IF(Z16="","","W"&WEEKNUM(Z16,2)) -> W37
A17: 45544 | B17: =IF(A17="","",YEAR(A17)) -> 2024 | C17: =IF(A17="","",TEXT(A17,"m")) -> 9 | D17: =IF(A17="","","W"&WEEKNUM(A17,2)) -> W37 | E17: Y24P0516 | F17: LB2101C-9 1 W2-BM-G1 | G17: 澳大利亚020-1 | H17: 宜胜照明1 | I17: 徐碧琳 | K17: 张煊 | L17: 客户反馈工单;Y24P0516、测试灯不亮， 经过将不良品进行分析，发现灯板焊盘脱落，导致灯不亮。 | M17: / | N17: / | O17: / | P17: 售后客诉 | Q17: 功能 | R17: 经过初步了解到因装配过程中，工人对插灯板时未注意，造成端子损伤。模拟测试同系列20pcs产品进行（震动+跌落+40℃恒温箱点亮2H），撬开灯罩未发现有灯板焊盘损伤不良，初步判定为装配时损伤了焊盘导致。 | S17: 人员作业 | T17: 1.增加巡检对球泡抽检，将此问题在同方案机种上验证。 未发现不良品 2.在同方案订单生产放置不良品，工人已经检出不良品。 模拟测试合格 3.将对客户反馈问题，内部协商签订质量保函，业务端回传给客户。 | U17: 1.通过客人反馈问题进行分析处理：1.端子焊盘在原有的位置加大，防止因为焊盘小，导致人员装配时间造成受力不均匀。 | V17: 是 | W17: 设计变更-预防 | X17: 宜胜照明1 | Y17: 研发六 | Z17: 45549 | AA17: 45546 | AB17: =IF(A17="","",_xlfn.IFS(AND(Z17=0,AA17=0),"未回复",AND(AA17<>0,Z17=0),"报错",AND(Z17>=NOW(),Z17<>0,AA17=0),"正常进行中",AND(AA17<>0,Z17>=AA17),"按时关闭",AND(Z17<>0,Z17<=AA17),"延期关闭",AND(AA17=0,Z17<NOW()),"延期未关闭")) -> 按时关闭 | AC17: 李俊林 | AD17: =IF(Z17="","",YEAR(Z17)) -> 2024 | AE17: =IF(Z17="","",TEXT(Z17,"m")) -> 9 | AF17: =IF(Z17="","","W"&WEEKNUM(Z17,2)) -> W37
A18: 45544 | B18: =IF(A18="","",YEAR(A18)) -> 2024 | C18: =IF(A18="","",TEXT(A18,"m")) -> 9 | D18: =IF(A18="","","W"&WEEKNUM(A18,2)) -> W37 | E18: M24H015 | F18: ST-WS7007 2-1800W3- WFT-G2 | G18: 巴西527 | H18: 宜胜照明1 | I18: 徐赢意 | J18: 赖长金 | K18: 丁亚双 | L18: 客验出现外箱变形，内部彩盒破损 | M18: 520 | N18: / | O18: / | P18: 客户验货 | Q18: 包装 | R18: 经过仓库排查，发现货物运输过程中货物掉下来，导致外箱摔下来，里面彩盒变形。 | S18: 人员作业 | T18: 针对此批外箱货物进行统一返工处理，彩盒更换，产品测试功能是否正常。 返工结果：产品功能测试正常。外箱增加发泡膜。 | U18: 1、针对外箱尺寸偏大，出现外箱变形，后续订单已经修改外箱尺寸，从订单;M24H033-1开始。外箱尺寸已经修改。原外箱尺寸35*31*27改成34.5x30x26cm。 2、因为外箱掉落导致内部彩盒变形，已经和仓库对接清楚，后续针对此客户货物，如出现货物掉下来，通知生产这边进行检查，内部产品是否损坏，彩盒是否出现不良。 3、仓库转移货物时，严禁货物超高堆积。按要求作业 | V18: 否 | W18: 人员培训 | X18: 其它事业部 | Y18: 优泰物流司 | Z18: 45544 | AA18: 45544 | AB18: =IF(A18="","",_xlfn.IFS(AND(Z18=0,AA18=0),"未回复",AND(AA18<>0,Z18=0),"报错",AND(Z18>=NOW(),Z18<>0,AA18=0),"正常进行中",AND(AA18<>0,Z18>=AA18),"按时关闭",AND(Z18<>0,Z18<=AA18),"延期关闭",AND(AA18=0,Z18<NOW()),"延期未关闭")) -> 按时关闭 | AC18: 李俊林 | AD18: 2024 | AE18: 9 | AF18: =IF(Z18="","","W"&WEEKNUM(Z18,2)) -> W37
A19: 45544 | B19: =IF(A19="","",YEAR(A19)) -> 2024 | C19: =IF(A19="","",TEXT(A19,"m")) -> 9 | D19: =IF(A19="","","W"&WEEKNUM(A19,2)) -> W37 | F19: 180路灯 | I19: 张美娟 | J19: 余元浩 | K19: 王超 | L19: 180路灯2PCS死灯 | N19: 2 | O19: =IFERROR(N19/M19,"") | P19: 售后客诉 | Q19: 功能 | R19: 经检查分析：45W驱动电源保险电阻熔断，元器件MOS损坏 60W灯板及驱动电源烧坏，已无法维修 LED失效可能原因： - 雷击影响：实际使用环境中可能遭受感应雷击（如静电和电磁感应雷击）导致驱动中保险丝熔断，尽管灯具浪涌测试合格，但实际环境更为复杂。雷击电压可达数千伏至几万伏，驱动中的保险丝也正是防止各种异常导致瞬间电流增大，保险丝熔断电路防止灯具主体受损 ，但若瞬间产生电压过高，超过灯具承受极限，就会导致灯具主体完全烧毁。 - 供电电压不稳：灯具连接的公共用电线路复杂，电压波动可能超出灯具承受范围导致保险丝熔断。 - 排除原因 - 灯珠和关键元器件温升：最大环温下灯珠和 IC 温升符合要求，不是灯具不亮的因素。 - LED 死灯与电路关系：死灯是其他原因造成的结果而非导致灯具不亮的原因，且短路 LED 复现灯板烧毁的假设不成立。 | S19: 其它 | T19: 对产品关键元器件温升进行测试，灯珠温升66.7℃（参考标准在60-80℃）驱动IC温升60.2℃（参考标准70-90℃） 浪涌（2500V)进行测试,测试结果OK 确保同批次产品符合标准 | U19: 针对驱动电源 - 加强对驱动电源供应商的管理，要求供应商对每批次元件提供更详细的质量检测报告，提高元件质量的稳定性。 - 优化驱动电源的生产质量管控流程，增加生产过程中的抽检频率，确保每一个驱动电源符合质量标准。 针对雷击、供电电压不稳问题 - 随时提供技术支持与服务，包括安装位置选择、接地方法等方面的建议，帮助客户减少灯具遭受雷击的风险；公共用电环境灯具使用，客户在电压不稳时可以采取的一些简单外部措施，如使用家用稳压器等，避免对灯具造成损坏。 | V19: 是 | W19: 其它 | Z19: 45547 | AA19: 45547 | AB19: =IF(A19="","",_xlfn.IFS(AND(Z19=0,AA19=0),"未回复",AND(AA19<>0,Z19=0),"报错",AND(Z19>=NOW(),Z19<>0,AA19=0),"正常进行中",AND(AA19<>0,Z19>=AA19),"按时关闭",AND(Z19<>0,Z19<=AA19),"延期关闭",AND(AA19=0,Z19<NOW()),"延期未关闭")) -> 按时关闭 | AC19: 赵纯杰 | AD19: =IF(Z19="","",YEAR(Z19)) -> 2024 | AE19: =IF(Z19="","",TEXT(Z19,"m")) -> 9 | AF19: =IF(Z19="","","W"&WEEKNUM(Z19,2)) -> W37
A20: 45549 | B20: 2024 | C20: 9 | D20: =IF(A20="","","W"&WEEKNUM(A20,2)) -> W37 | E20: P24R023/R032/R033 | F20: 球泡 | G20: 俄罗斯482-3 | H20: 宜胜照明1 | L20: 1.P24R023 LBD B35-10W-840-E14 R 灯头变形6pcs 2.P24R023 LED B35-8W-865-E14 R 1pc电解端子起翘 加抽100pcs（1pc保险电阻端子起翘）客户形容灯头很顺滑 测试扭力没有阻力 3. P24R023 LBD MR16-11W-840-GU5.3 R 1PC不亮 保险电阻端子起翘（未加抽） 4. P24R023 LBD P45-10W-865-B27 R 功率不足 实测6.47W 客户要求≥6.5W 5.P24R023 LED P45-8W-865-E27 R IPC 扭力不过（未加抽） 6. P24R032 LED A60-15W-827-E27 R IPC 不亮 1pc混灯 瓦数偏低（实测8.4W 要求＞8.5w） 扭力不过1pc 7.P24R032 LED A60-15W-865-E27 R 4pcs 不亮（客户发现一个 未加抽） 瓦数偏低（实测8.4W 要求≥8.5W） | R20: 经过确认此问题为生产作业问题。 | V20: 否 | AB20: =IF(A20="","",_xlfn.IFS(AND(Z20=0,AA20=0),"未回复",AND(AA20<>0,Z20=0),"报错",AND(Z20>=NOW(),Z20<>0,AA20=0),"正常进行中",AND(AA20<>0,Z20>=AA20),"按时关闭",AND(Z20<>0,Z20<=AA20),"延期关闭",AND(AA20=0,Z20<NOW()),"延期未关闭")) -> 未回复 | AD20: =IF(Z20="","",YEAR(Z20)) | AE20: =IF(Z20="","",TEXT(Z20,"m")) | AF20: =IF(Z20="","","W"&WEEKNUM(Z20,2))
A21: 45561 | B21: =IF(A21="","",YEAR(A21)) -> 2024 | C21: =IF(A21="","",TEXT(A21,"m")) -> 9 | D21: =IF(A21="","","W"&WEEKNUM(A21,2)) -> W39 | E21: M24S064K M22K044 | F21: 智能插座 | G21: 阿根廷037 | H21: 宜胜照明1 | L21: 产品额定电流10A，在220V情况下最大负载2200W，客户实际使用过程中，电流达到7/8A，产品会损坏，已回收50PCS大货，产品经理实测产品出现问题 | M21: 5200 8000 | N21: 50 | O21: / | P21: 售后客诉 | Q21: 功能 | R21: 供应商也过来现场测试过了、初步分析为供应商的继电器未达到10A的标准。上限10A、导致现场出现2个问题、底电压测试功能正常、继电器内部触点无任何变化。、当电压放到9A测试、长开测试1小时、连续开关测试1小时、继电器内部触电呈现发蓝发红现象。初步分析此现象为过载状态。 经过确认供应商继电器有问题，掉落地上以后，测试不良 | S21: 结构设计 | T21: 经过和供应商产品经理确认，此批继电器为供应商问题，已经和供应商确认。 | V21: 是 | Z21: 45572 | AA21: 45572 | AB21: 按时关闭 | AC21: 李俊林 | AD21: 2024 | AE21: 9 | AF21: 39W
A22: 45573 | B22: =IF(A22="","",YEAR(A22)) -> 2024 | C22: =IF(A22="","",TEXT(A22,"m")) -> 10 | D22: =IF(A22="","","W"&WEEKNUM(A22,2)) -> W41 | E22: Y24P0516 | F22: 球泡 | G22: 洪都拉斯008 | H22: 宜胜照明1 | L22: 产品点亮测试，灯不亮。 | M22: / | N22: / | O22: / | P22: 售后客诉 | Q22: 功能 | R22: 1.产生原因：将不良品进行分析，发现产品芯片破损，经过测量发现芯片短路，造成产品灯微亮，测试无输出，将产品寄回供应商进行分析，发现回传报告显示，芯片因为芯片破损导致局部短路温度过高。造成产品灯微亮，测试无功率。 将不良更换芯片后面测试正常。 2.流出原因：经与供应商确认，此问题是IC小批次不良，在长期在低压100V老化时存在风险，而此款产品我司同客户约定测试电压为AC120V及AC220V，生产中仅在120V以上做了长期老化，没能发现问题，致使产品流出。 | S22: 过程工艺 | T22: 增加老化时间，从原来的1小时更改成2小时 | U22: 1.通过以上自查进行分析处理：1.修改老化SOP设置 从原有的120V 修正为低压100V 常压 120V 高压140V； | V22: 否 | Y22: 生产一 | Z22: 45573 | AA22: 45573 | AB22: =IF(A22="","",_xlfn.IFS(AND(Z22=0,AA22=Z22>0,Z22=0),"报错",AND(Z22>=NOW(),Z22<>0,AA22=0),"正常进行中",AND(AA22<>0,Z22>=AA22),"按时关闭",AND(Z22<>0,Z22<=AA22),"延期关闭",AND(AA22=0,Z22<NOW()),"延期未关闭")) -> 按时关闭 | AC22: 李俊林 | AD22: =IF(Z22="","",YEAR(Z22)) -> 2024 | AE22: =IF(Z22="","",TEXT(Z22,"m")) -> 10 | AF22: =IF(Z22="","","W"&WEEKNUM(Z22,2)) -> W41
A23: 45575 | B23: =IF(A23="","",YEAR(A23)) -> 2024 | C23: =IF(A23="","",TEXT(A23,"m")) -> 10 | D23: =IF(A23="","","W"&WEEKNUM(A23,2)) -> W41 | E23: M24H026 | F23: 智能插座 | G23: 巴西527 | H23: 宜胜照明1 | L23: 客户发了一个客诉邮件，关于ETS 两开单插的： 527的终端客户将设备插入插座时，发生了短路，导致产品损坏无法修复。但是用户家里所有的保护装置都被触发了，所以只有ETS 2002被损坏了。在检查产品时，发现插座中的接地连接器在出厂时是弯曲的，用户在连接设备时，引脚会推动已经弯曲的金属连接器而导致短路。 | M23: / | N23: / | O23: / | P23: 售后客诉 | Q23: 功能 | R23: 1.经过初步分析为生产时未测试地线位置接触，导致客户使用过程中，因为地线接触到火线，造成炸机 | S23: 过程工艺 | T23: 1.车间是对每一个插座用标准的巴西插头进行插入测试的，能正常插拔就是OK的。 另外，客户那边的允收标准也同步问一下。 目前大货是按给客户送样的产品生产的，客户那边应该也是做了证书的。对于客户提出的问题，现在设计上对接地的金属插片进行了调整 | U23: 规格地线端子使用规格 | V23: 是 | Y23: 研发六 | Z23: 45577 | AA23: 45577 | AB23: =IF(A23="","",_xlfn.IFS(AND(Z23=0,AA23=0),"未回复",AND(AA23<>0,Z23=0),"报错",AND(Z23>=NOW(),Z23<>0,AA23=0),"正常进行中",AND(AA23<>0,Z23>=AA23),"按时关闭",AND(Z23<>0,Z23<=AA23),"延期关闭",AND(AA23=0,Z23<NOW()),"延期未关闭")) -> 按时关闭 | AC23: 李俊林 | AD23: =IF(Z23="","",YEAR(Z23)) -> 2024 | AE23: =IF(Z23="","",TEXT(Z23,"m")) -> 10 | AF23: =IF(Z23="","","W"&WEEKNUM(Z23,2)) -> W41
A24: 45614 | B24: =IF(A24="","",YEAR(A24)) -> 2024 | C24: =IF(A24="","",TEXT(A24,"m")) -> 11 | D24: =IF(A24="","","W"&WEEKNUM(A24,2)) -> W47 | E24: M24A002 | F24: 智能插座 | G24: 巴西527 | H24: 宜胜照明1 | L24: 客户验货中发现： 1. 外观问题： 1.1.插座划伤，轻微*3。 1. 2.玻璃背部划伤*5。 1. 3.玻璃面板边缘破损*2 。 | M24: / | N24: / | O24: / | P24: 售后客诉 | Q24: 外观 | R24: 1.插座划伤，轻微：塑料件旁边有一个电子开关需要按压测试，生产人员使用的测试工具不规范（PCB板边），较为锋利，测试时会误伤塑胶件。 2.玻璃背部划伤：（供应商）覆底膜进入机器抽真空后，在尾分使用美工刀作业，造成玻璃背部划伤。 3.玻璃面板边缘破损：该订单为返工订单，返工过程中需要拆开玻璃进行内部测试，拆开后的玻璃摆放堆积，造成相互之间有磕碰。 | S24: 过程工艺 | T24: 1.针对塑料件划伤：目前已经对该测试岗位重新制定按压工具（胶棒），避免划伤问题。 模拟测试100台，塑料件外观检查未发现外观不良 2.玻璃背部划伤： 供方措施：暂未回复 我方措施：返工时针对玻璃保护膜需要撕下来看划痕。 请业务端与客户沟通，撕开膜以后外观确认。撕膜后重新覆膜的状态对比已经放置在报告后端。如确认OK，后续将此问题增加进检验要求内部。 3.玻璃面板边缘破损：本次返工时，增加玻璃放置箱，只能单排放置，不得有相互堆积、错乱放置 | U24: 1、使用重新制定按压工具（胶棒），可有效避免划伤问题。 2.对于玻璃内部划痕的问题以反馈供应商进行排查划伤原因。 3.制定SOP，并明确返工作业流程，以及摆放方式，巡检增加返工过程中生产，是否按SOP要求作业。 | V24: 是 | W24: 防呆防错 | X24: 宜胜照明1 | Y24: 生产一 | Z24: 45616 | AA24: 45616 | AB24: =IF(A24="","",_xlfn.IFS(AND(Z24=0,AA24=0),"未回复",AND(AA24<>0,Z24=0),"报错",AND(Z24>=NOW(),Z24<>0,AA24=0),"正常进行中",AND(AA24<>0,Z24>=AA24),"按时关闭",AND(Z24<>0,Z24<=AA24),"延期关闭",AND(AA24=0,Z24<NOW()),"延期未关闭")) -> 按时关闭 | AD24: =IF(Z24="","",YEAR(Z24)) -> 2024 | AE24: =IF(Z24="","",TEXT(Z24,"m")) -> 11 | AF24: =IF(Z24="","","W"&WEEKNUM(Z24,2)) -> W47
A25: 45620 | B25: =IF(A25="","",YEAR(A25)) -> 2024 | C25: =IF(A25="","",TEXT(A25,"m")) -> 11 | D25: =IF(A25="","","W"&WEEKNUM(A25,2)) -> W47 | E25: M24H022 | F25: 智能插座 | G25: 巴西527 | H25: 宜胜照明1 | L25: 客户反馈外箱打开后发现内部彩盒装混装，内部标签，产品一致，彩盒出现混装。 1.工单数量合计：5080台，挑选出88台。 | M25: 5080 | N25: 88 | O25: =IFERROR(N25/M25,"") -> 0.017322835 | P25: 售后客诉 | Q25: 包装 | R25: 1.通过目前仓库物料排查，发现内部仓库未规范摆放物料现象。将此问题进行复盘，物料摆放过近，容易造成物料领用过程中料混。 2.生产过程中，全检验人员检查力度不够，未及时发现问题存在。 3.彩盒装混装已转供方分析处理。（供应商）初步分析为人员变动，在包装过程中未及时清理上工单，造成将上款包材混装。 | S25: 人员作业 | T25: 1.提供客户反馈问题，将内部已经生产完成订单进行排查，统计数量，做整批返工处理。 2.已完成成品合计：24800台，将整批全部返工。 附件返工视频---24800台全部返工未出现彩盒混装。 3.彩盒装混装： 供方措施：暂未回复 我方措施：通知仓库接受物料过程中，检查是否将物料排放整齐，拒绝堆积物料送入公司。 | U25: 1.仓库物料摆放整改，将物料进行分类，防止运输过程，以及物料摆放，进行缠绕膜方式，防止物料混在一起。 2.规范人员检验方法，SOP增加检验标准。 | V25: 是 | W25: 其它 | X25: 宜胜照明1 | Y25: 生产一 | Z25: 45622 | AA25: 45622 | AB25: =IF(A25="","",_xlfn.IFS(AND(Z25=0,AA25=0),"未回复",AND(AA25<>0,Z25=0),"报错",AND(Z25>=NOW(),Z25<>0,AA25=0),"正常进行中",AND(AA25<>0,Z25>=AA25),"按时关闭",AND(Z25<>0,Z25<=AA25),"延期关闭",AND(AA25=0,Z25<NOW()),"延期未关闭")) -> 按时关闭 | AD25: =IF(Z25="","",YEAR(Z25)) -> 2024 | AE25: =IF(Z25="","",TEXT(Z25,"m")) -> 11 | AF25: =IF(Z25="","","W"&WEEKNUM(Z25,2)) -> W48
A26: 45644 | B26: =IF(A26="","",YEAR(A26)) -> 2024 | C26: =IF(A26="","",TEXT(A26,"m")) -> 12 | D26: =IF(A26="","","W"&WEEKNUM(A26,2)) -> W51 | E26: A522M054 | F26: BL212-15W-PIR | G26: 澳大利亚1283 | H26: 宜胜照明3 | L26: 2022年A522M054订单，出货时间在2023年1月。客户在2024年11月反馈该项目有320PCS灯具出现半亮或不亮现象 | M26: 2070 | N26: 230 | O26: =IFERROR(N26/M26,"") -> 0.11111111 | P26: 售后客诉 | Q26: 功能 | R26: 不良现象分析：分别对客户寄回4PCS产品进行检查，均为电容中间灯珠死灯导致产品不亮，电解电容中间灯珠为灯板线路第一颗灯珠，连接此灯珠两端，其余整灯可正常点亮。4PC灯具不良现象完全一致。 根本原因分析： 1. 电气应力过大：由于灯具安装在人流量密集区域，感应频繁开关，开关瞬间产生较大电流冲击。而第一颗灯珠在电路中处于起始位置，承受的电流冲击相对更大，长时间累积导致灯珠内部芯片受损，最终死灯。 2. 线性方案局限性：采用的线性方案在应对频繁开关和大电流冲击时，缺乏有效的电流稳定和保护机制。无法有效分散或缓冲瞬间大电流对灯珠的影响，使得灯珠更容易因电气过载而损坏。 | S26: 电子设计 | T26: 与客户沟通，为受影响的客户提供临时替换320pcs灯具，确保其正常使用，减少对客户业务的影响。 | U26: 措施建议： 1. 电路优化： 更改灯具电路线性方案，采用具备软启动功能和电流限制保护的驱动方案，降低开关瞬间电流冲击幅度，均匀分配电流至每颗灯珠，减少单颗灯珠承受的电气应力。 2.使用质量更好可靠性更高的灯珠，可延长一些灯具使用寿命。 | V26: 否 | W26: 纠错 | X26: 宜胜照明3 | Y26: 研发二 | Z26: 45651 | AA26: 45651 | AB26: =IF(A26="","",_xlfn.IFS(AND(Z26=0,AA26=0),"未回复",AND(AA26<>0,Z26=0),"报错",AND(Z26>=NOW(),Z26<>0,AA26=0),"正常进行中",AND(AA26<>0,Z26>=AA26),"按时关闭",AND(Z26<>0,Z26<=AA26),"延期关闭",AND(AA26=0,Z26<NOW()),"延期未关闭")) -> 按时关闭 | AD26: =IF(Z26="","",YEAR(Z26)) -> 2024 | AE26: =IF(Z26="","",TEXT(Z26,"m")) -> 12 | AF26: =IF(Z26="","","W"&WEEKNUM(Z26,2)) -> W52
A27: 45649 | B27: =IF(A27="","",YEAR(A27)) -> 2024 | C27: =IF(A27="","",TEXT(A27,"m")) -> 12 | D27: =IF(A27="","","W"&WEEKNUM(A27,2)) -> W52 | E27: Z24V002-1 | F27: 方形投光灯_LG189-150W | G27: 中国2354 | H27: 宜胜照明3 | L27: 150W投光灯玻璃内部水汽 | M27: 500 | N27: 350 | O27: =IFERROR(N27/M27,"") -> 0.7 | P27: 售后客诉 | Q27: 安规 | R27: 原因分析：热空气遇冷凝结 投光灯点亮后，灯体内的灯泡等发光元件会产生热量，使灯体内的空气温度升高。当热空气遇到冰冷的灯体外壳（在寒冷天气下）时，热空气就会迅速降温，其中的水蒸气达到饱和状态后就会凝结成小水滴，形成水汽。这就如同冬天室内温暖的空气遇到冰冷的窗户玻璃时会在玻璃上形成水珠一样 | S27: 结构设计 | T27: 与客户沟通，为受影响的客户提供临时替换该订单有问题产品，确保其正常使用，减少对客户业务的影响。 | U27: 改善措施：灯体增加呼吸孔，平衡灯具内部的气压，同时阻止外界的水汽进入。在寒冷天气下，它有助于维持灯具内部环境的相对稳定。 该款产品结构增加呼吸孔已于2024年6月进行变更。 | V27: 是 | W27: 设计变更-预防 | X27: 宜胜照明3 | Y27: 研发一 | Z27: 45651 | AA27: 45651 | AB27: =IF(A27="","",_xlfn.IFS(AND(Z27=0,AA27=0),"未回复",AND(AA27<>0,Z27=0),"报错",AND(Z27>=NOW(),Z27<>0,AA27=0),"正常进行中",AND(AA27<>0,Z27>=AA27),"按时关闭",AND(Z27<>0,Z27<=AA27),"延期关闭",AND(AA27=0,Z27<NOW()),"延期未关闭")) -> 按时关闭 | AD27: =IF(Z27="","",YEAR(Z27)) -> 2024 | AE27: =IF(Z27="","",TEXT(Z27,"m")) -> 12 | AF27: =IF(Z27="","","W"&WEEKNUM(Z27,2)) -> W52
A28: 45670 | B28: =IF(A28="","",YEAR(A28)) -> 2025 | C28: =IF(A28="","",TEXT(A28,"m")) -> 1 | D28: =IF(A28="","","W"&WEEKNUM(A28,2)) -> W3 | E28: R23X0418 | F28: HL120C-200W高顶灯 | G28: 俄罗斯745 | H28: 宜胜照明3 | L28: 订单总数量3780pcs，200W这一款1200pcs，客户检查400pcs，其中150pcs壳体吊环螺丝孔无螺纹，不良比例37.5% | M28: 1200 | N28: 150 | O28: =IFERROR(N28/M28,"") -> 0.125 | P28: 售后客诉 | Q28: 内部 | R28: 发生原因：供应商生产过程中攻丝设备出现故障，导致部分螺丝孔未攻出完整螺纹。同时，供应商的生产人员在操作过程中未及时发现和处理设备故障，也未对加工后的产品进行严格检验。 流出原因：来料及制程对结构安装配件存在漏检现象或抽检比例不足 | S28: 来料不良 | T28: 与客户沟通，有以下临时措施可供选择： 1.使用M10丝锥进行攻丝处理，人工费用由我司承担； 2.换货处理，不良品进行退换货处理； 3.折价处理，吊环螺丝孔不影响产品功能正常使用，只是安装过程可能会对客户造成一些影响，可根据不良率对该批产品折价赔偿处理。 | U28: 1.供应商整改：我司已于2024年7月底因该供应商质量不符合公司要求且无整改意向，而中断与该供应商合作；后续继续加强对供应商管理，定期对供应商进行考核。 2.合理调整抽样方案，增加样本抽样数量，加强生产过程巡检频率，螺纹孔纳入产线外观检验人员必检项目，防止不良流出，成品检验抽检需对配件包物料进行实配 3.建立质量预警机制：与供应商共享质量数据，当出现质量波动或异常趋势时，及时发出预警，共同分析原因并采取措施。 4.定期审核与评估：定期对供应商进行审核，包括生产过程、质量控制体系等方面。对公司内部的检验流程、生产工艺等进行评估，持续优化改善。 5.案例培训：整理此次问题案例在公司内部进行培训，提高全体人员质量意识。 | V28: 否 | W28: 供应商改善 | X28: 计划采购部 | Y28: 供方管理组 | Z28: 45671 | AA28: 45671 | AB28: =IF(A28="","",_xlfn.IFS(AND(Z28=0,AA28=0),"未回复",AND(AA28<>0,Z28=0),"报错",AND(Z28>=NOW(),Z28<>0,AA28=0),"正常进行中",AND(AA28<>0,Z28>=AA28),"按时关闭",AND(Z28<>0,Z28<=AA28),"延期关闭",AND(AA28=0,Z28<NOW()),"延期未关闭")) -> 按时关闭 | AD28: =IF(Z28="","",YEAR(Z28)) -> 2025 | AE28: =IF(Z28="","",TEXT(Z28,"m")) -> 1 | AF28: =IF(Z28="","","W"&WEEKNUM(Z28,2)) -> W3
A29: 45672 | B29: =IF(A29="","",YEAR(A29)) -> 2025 | C29: =IF(A29="","",TEXT(A29,"m")) -> 1 | D29: =IF(A29="","","W"&WEEKNUM(A29,2)) -> W3 | E29: A224M005 | F29: BL111C-20W | G29: 飞利浦-JP | H29: 宜胜照明3 | L29: 灯具不亮 | M29: 400 | N29: 36 | O29: =IFERROR(N29/M29,"") -> 0.09 | P29: 售后客诉 | Q29: 功能 | R29: 1.不排除灯珠本身质量问题的损坏（可能性极小，三星灯珠） 2.导热硅脂未贴于芯片及元器件位置，元器件温度过高电路不稳失衡，但更换灯珠后，一直老化无任何异常；3.PCB底部铜箔有发黄迹象，判定驱动处于高温环境中，实际测试温升OK，可推测产品实际应用环境高于产品要求！高温环境中驱动稳定性会有一定程度上的削弱（抗浪涌抗冲击能力变差） 4.现场安装环境(未知），如安装环境温度、周边电路电压、电流稳定性等 | S29: 电子设计 | T29: 客户回复使用环境为-35℃冷库环境，要求灯珠寄供应商分析 | V29: 否 | W29: 纠错 | X29: 宜胜照明3 | Y29: 研发二 | Z29: 45679 | AA29: 45679 | AB29: =IF(A29="","",_xlfn.IFS(AND(Z29=0,AA29=0),"未回复",AND(AA29<>0,Z29=0),"报错",AND(Z29>=NOW(),Z29<>0,AA29=0),"正常进行中",AND(AA29<>0,Z29>=AA29),"按时关闭",AND(Z29<>0,Z29<=AA29),"延期关闭",AND(AA29=0,Z29<NOW()),"延期未关闭")) -> 按时关闭 | AD29: =IF(Z29="","",YEAR(Z29)) -> 2025 | AE29: =IF(Z29="","",TEXT(Z29,"m")) -> 1 | AF29: =IF(Z29="","","W"&WEEKNUM(Z29,2)) -> W4
A30: 45699 | B30: =IF(A30="","",YEAR(A30)) -> 2025 | C30: =IF(A30="","",TEXT(A30,"m")) -> 2 | D30: =IF(A30="","","W"&WEEKNUM(A30,2)) -> W7 | E30: W24T023 | F30: ST-LC2201E-5.5W2-WF5 LC2221E4-7W2-TD-G1-21 | G30: 德国675 | H30: 宜胜照明1 | L30: 客户反馈 2024年W24T023订单，出货时间在2024年12月，订单两款产品，分别为货号990000102数量6000pcs（共20箱），货号990000132数量3900pcs（共13箱），客户实际收到产品990000102数量5700pcs（19箱）；990000132数量4200pcs（14箱），造成客户多支付348美金，客户需要下次订单时扣除该笔费用。 | M30: 6000/3900 | N30: 300 | O30: 0.05 | P30: 售后客诉 | Q30: 包装 | R30: 不良原因排查： 1.对生产信息进行排查，生产投料数量与入库数量、成品验货记录均与订单一致，排除两款产品一款多做一款少做的可能； 2.客户按外箱货号（990000102,990000132）多次清点数量，确认990000102少一箱，990000132多一箱，排查仓库发货记录及仓库库存信息，该订单两款产品入库后分开放置，出货时为同一货柜出货，货物订单数量全部发出； 3.排查外箱采购记录，990000102采购外箱21个，990000132采购外箱14个，两款产品各有多采购一个外箱备用，生产包装未仔细核对外箱信息，误将不同规格型号装入错误外箱 | S30: 其它 | T30: 与客户沟通，为避免客户继续清点产品数量信息，而要求外部仓库做任何移动货物或者关于货物的任何事情支付额外费用，同意客户下次订单时扣除该笔费用，同时针对此次问题向客户表达歉意。 | U30: 1.大货订单首件核对后生产并对外箱PO号进行点检存档记录，确保外箱信息正确。 2.大货生产完成摆托PO号朝外入库前确认外箱PO号内容是否正确。 3.尾数产品所有物料按照工单放置在托盘上使用缠绕膜封好并做好标识。 4.订单扫尾按照新工单进行首件确认合格后才可进行收尾并对外箱PO号进行点检确认。 | V30: 否 | W30: 流程优化 | X30: 宜胜照明1 | Y30: 生产一 | Z30: 45668 | AA30: 45668 | AB30: =IF(A30="","",_xlfn.IFS(AND(Z30=0,AA30=0),"未回复",AND(AA30<>0,Z30=0),"报错",AND(Z30>=NOW(),Z30<>0,AA30=0),"正常进行中",AND(AA30<>0,Z30>=AA30),"按时关闭",AND(Z30<>0,Z30<=AA30),"延期关闭",AND(AA30=0,Z30<NOW()),"延期未关闭")) -> 按时关闭 | AD30: =IF(Z30="","",YEAR(Z30)) -> 2025 | AE30: =IF(Z30="","",TEXT(Z30,"m")) -> 1 | AF30: =IF(Z30="","","W"&WEEKNUM(Z30,2)) -> W2
A31: 45699 | B31: =IF(A31="","",YEAR(A31)) -> 2025 | C31: =IF(A31="","",TEXT(A31,"m")) -> 2 | D31: =IF(A31="","","W"&WEEKNUM(A31,2)) -> W7 | E31: M23H036-B | F31: ST-LB208-10W3-WF5LC-G1 | G31: 巴西527 | H31: 宜胜照明1 | L31: 客户反馈订单M23H036-B球泡灯，型号ST-LB208-10W3-WF5LC-G1，订单数量25200pcs，发现5pcs手机APP控制关灯后，灯珠有余亮现象。 | M31: 25200 | N31: 5 | O31: =IFERROR(N31/M31,"") -> 0.0001984127 | P31: 售后客诉 | Q31: 功能 | R31: 1.对客户退回样品拆机检查，为KP18058ESPA芯片失效导致手机APP控制关灯后余亮，更换芯片后，产品功能恢复正常； 2.对KP18058ESPA失效进行FT复测，测试结果显示OUT4、OUT5耐压异常偏低； 3.进一步对失效芯片进行Decap拆封分析，Decap拍照无明显异常，芯片表面无明显异常； 4.失效芯片EMMI分析（PIN6加电压）：OUT4 MOS附件存在微小漏电亮点，判断击穿瞬间能量较小，推测为ESD静电击穿； 综上：不良样品手机APP控制关灯后余量现象为ESD静电击穿芯片导致功能异常。 | S31: 过程工艺 | T31: 不良产品更换货 | U31: 1.开线对设备和静电环进行接地点检 2.接触到灯板和电源的工位佩戴静电环和手套 3.灯板电源使用静电盒分开放置不能堆积 | V31: 否 | W31: 人员培训 | X31: 宜胜照明1 | Y31: 生产一 | Z31: 45670 | AA31: 45670 | AB31: =IF(A31="","",_xlfn.IFS(AND(Z31=0,AA31=0),"未回复",AND(AA31<>0,Z31=0),"报错",AND(Z31>=NOW(),Z31<>0,AA31=0),"正常进行中",AND(AA31<>0,Z31>=AA31),"按时关闭",AND(Z31<>0,Z31<=AA31),"延期关闭",AND(AA31=0,Z31<NOW()),"延期未关闭")) -> 按时关闭 | AD31: =IF(Z31="","",YEAR(Z31)) -> 2025 | AE31: =IF(Z31="","",TEXT(Z31,"m")) -> 1 | AF31: =IF(Z31="","","W"&WEEKNUM(Z31,2)) -> W3
A32: 45706 | B32: =IF(A32="","",YEAR(A32)) -> 2025 | C32: =IF(A32="","",TEXT(A32,"m")) -> 2 | D32: =IF(A32="","","W"&WEEKNUM(A32,2)) -> W8 | E32: D24A035 | F32: T100/T120/T140/T160光源板 | G32: 突尼斯100 | H32: 宜胜照明1 | L32: 客户反馈订单D24A035散件发货4款T泡光源板端子起翘，不良比例50% | M32: 50500 | O32: 0.5 | P32: 售后客诉 | Q32: 功能 | R32: 1.焊点牢固可靠性确认：库存查询该订单同批次4款灯板各有5PC在仓库，对端子焊点做30N-1min推拉力测试，测试结果合格。 2.包装方式：灯板采用背靠背的包装方式，背面端子有几毫米凸起，运输过程端子会直接相互摩擦挤压，长途运输过程端子会持续受力 3.运输过程：产品要经过三次装箱及卸货及长途运输 综上所述：灯板采用背面端子凸起面紧靠包装方式，长途运输过程端子持续受力摩擦及多次装卸货，导致端子脱落起翘。 | S32: 包装设计 | T32: 临时措施：与客户沟通，由客户对本批次端子起翘不良灯板进行返工维修，我司提供返工视频指导及所需工具型号（烙铁、锡丝），我司赔偿返工费用或产品进行折扣处理。 维修方案：1.拿小刀对起翘脱落焊盘附近的铜箔线路轻轻刮动，刮掉表面白色绝缘保护层，露出线路铜箔即可；2.用烙铁和锡丝将刮开的铜箔同端子引脚进行加锡焊接，覆盖链接实现串联。 | U32: 更改设计，将端子更改为平口端子，避免铝基本板背面端子凸出部分在运输过程相互摩擦受力而导致端子脱落。包装进行紧凑包装，防止运输途中松动相互碰撞 | V32: 是 | W32: 设计变更-预防 | X32: 宜胜照明1 | Y32: 研发六 | Z32: 45708 | AA32: 45708 | AB32: =IF(A32="","",_xlfn.IFS(AND(Z32=0,AA32=0),"未回复",AND(AA32<>0,Z32=0),"报错",AND(Z32>=NOW(),Z32<>0,AA32=0),"正常进行中",AND(AA32<>0,Z32>=AA32),"按时关闭",AND(Z32<>0,Z32<=AA32),"延期关闭",AND(AA32=0,Z32<NOW()),"延期未关闭")) -> 按时关闭 | AD32: =IF(Z32="","",YEAR(Z32)) -> 2025 | AE32: =IF(Z32="","",TEXT(Z32,"m")) -> 2 | AF32: =IF(Z32="","","W"&WEEKNUM(Z32,2)) -> W8
A33: 45708 | B33: =IF(A33="","",YEAR(A33)) -> 2025 | C33: =IF(A33="","",TEXT(A33,"m")) -> 2 | D33: =IF(A33="","","W"&WEEKNUM(A33,2)) -> W8 | E33: Z24V002-2 | F33: LB101-7W-9W-15W壳体 | G33: 正泰 | H33: 宜胜照明1 | L33: 1. 大批量外箱包含我司产品标贴 2. 7W，9W和15W尾数箱壳体摆放不当，并使用单层外箱导致外箱破损，并且壳体刮花 | M33: 10326 | N33: 10326 | O33: 1 | P33: 售后客诉 | Q33: 包装 | R33: 产品为委外产品，发货使用原供应商包装未进行更换 | S33: 包装设计 | T33: 1.外箱标贴全部更换 2.破损程度大的外箱全部更换 3.轻度破损外箱封箱胶打补丁 4.结构件点货 | X33: 计划采购部 | Y33: 供方管理组 | Z33: 45708 | AA33: 45708 | AB33: =IF(A33="","",_xlfn.IFS(AND(Z33=0,AA33=0),"未回复",AND(AA33<>0,Z33=0),"报错",AND(Z33>=NOW(),Z33<>0,AA33=0),"正常进行中",AND(AA33<>0,Z33>=AA33),"按时关闭",AND(Z33<>0,Z33<=AA33),"延期关闭",AND(AA33=0,Z33<NOW()),"延期未关闭")) -> 按时关闭 | AD33: =IF(Z33="","",YEAR(Z33)) -> 2025 | AE33: =IF(Z33="","",TEXT(Z33,"m")) -> 2 | AF33: =IF(Z33="","","W"&WEEKNUM(Z33,2)) -> W8
A34: 45708 | B34: =IF(A34="","",YEAR(A34)) -> 2025 | C34: =IF(A34="","",TEXT(A34,"m")) -> 2 | D34: =IF(A34="","","W"&WEEKNUM(A34,2)) -> W8 | E34: A119S023 | F34: 180路灯 70W 4000K SPD | G34: 朗德万斯 | H34: 宜胜照明3 | L34: 客户在一个城镇完成了400套路灯的销售。这些灯具安装正确；然而，174只灯遇到了同样的问题。发现的问题是LED短路并烧坏。测试显示，驱动器向LED提供的是正确的电压，因此问题似乎源于LED模块本身; | M34: 400 | N34: 174 | O34: =IFERROR(N34/M34,"") -> 0.435 | P34: 售后客诉 | Q34: 功能 | R34: 目前收到的 3 个客退品，经过分析结果如下：1 个产品测试合格，2 个产品死灯，主要原因为 LED 灯板输入线虚焊导致不良。 电源线虚焊原因： 1：经查原工艺要求电烙铁温度为370±10℃，温度较低，焊接时Pcb焊盘未得到有效预热，导致虚焊。 2：操作人员焊接线到灯板上时，焊接时烙铁先与锡线接触，然后再与焊盘接触，导致虚焊 。 | S34: 过程工艺 | T34: 不良产品更换货或赔偿 | U34: 整改措施:1.焊接温度由19年的370±10℃变更为现在的400±10℃ 2：焊接工位更换为自动出锡电烙铁，自动电烙铁烙铁头会先接触焊盘预热，保证焊点可靠性 3.作业人员按工艺技术要求进行焊接作业，焊接完成后对焊点质量进行检查，确保焊点饱满、圆滑无毛刺、无虚焊、浮高、拉尖现象。 预防措施：1.每日开线前电烙铁温度进行点检，确保温度达到预设范围； 2.IPQC每日开工对设电烙铁点检情况进行核查 。 3.IPQC每2小时一次的巡检，要对重点岗位（焊接岗等）技术要求执行情况如焊接温度、焊接手法、焊接完成是否有进行目检动作等进行检查，确保生产要求执行； 4.对焊接岗位定人定岗，新员工需经过培训，有工程工艺确认合格后方可上岗； 5.准备一些常见不良图片示例放置于各岗位，增强员工质量意识。 | V34: 否 | W34: 工艺优化 | X34: 宜胜照明3 | Y34: 生产三 | Z34: 45708 | AA34: 45708 | AB34: =IF(A34="","",_xlfn.IFS(AND(Z34=0,AA34=0),"未回复",AND(AA34<>0,Z34=0),"报错",AND(Z34>=NOW(),Z34<>0,AA34=0),"正常进行中",AND(AA34<>0,Z34>=AA34),"按时关闭",AND(Z34<>0,Z34<=AA34),"延期关闭",AND(AA34=0,Z34<NOW()),"延期未关闭")) -> 按时关闭 | AD34: =IF(Z34="","",YEAR(Z34)) -> 2025 | AE34: =IF(Z34="","",TEXT(Z34,"m")) -> 2 | AF34: =IF(Z34="","","W"&WEEKNUM(Z34,2)) -> W8
A35: 45710 | B35: =IF(A35="","",YEAR(A35)) -> 2025 | C35: =IF(A35="","",TEXT(A35,"m")) -> 2 | D35: =IF(A35="","","W"&WEEKNUM(A35,2)) -> W8 | E35: T24K062 | F35: USB线路板 | G35: 优耐特 | H35: 宜胜照明1 | L35: 1.客户组装后发现充电时噪音大 2.板子无法给iphone15充电（客户指定要求） | M35: 9000 | N35: 9000 | O35: =IFERROR(N35/M35,"") -> 1 | P35: 售后客诉 | Q35: 功能 | R35: 电子设计方案问题 | S35: 电子设计 | T35: 客户未组装产品运回工厂返工，已组装产品有工厂安排人员至现场随线返工：1.噪音更换贴片电容2.更换C口小板 | U35: 变更电子方案 | V35: 是 | W35: 设计变更-预防 | X35: 宜胜照明1 | Y35: 研发十 | Z35: 45710 | AA35: 45710 | AB35: =IF(A35="","",_xlfn.IFS(AND(Z35=0,AA35=0),"未回复",AND(AA35<>0,Z35=0),"报错",AND(Z35>=NOW(),Z35<>0,AA35=0),"正常进行中",AND(AA35<>0,Z35>=AA35),"按时关闭",AND(Z35<>0,Z35<=AA35),"延期关闭",AND(AA35=0,Z35<NOW()),"延期未关闭")) -> 按时关闭 | AD35: =IF(Z35="","",YEAR(Z35)) -> 2025 | AE35: =IF(Z35="","",TEXT(Z35,"m")) -> 2 | AF35: =IF(Z35="","","W"&WEEKNUM(Z35,2)) -> W8
A36: 45344 | B36: =IF(A36="","",YEAR(A36)) -> 2024 | C36: =IF(A36="","",TEXT(A36,"m")) -> 2 | D36: =IF(A36="","","W"&WEEKNUM(A36,2)) -> W8 | E36: M22H036/M22H037 | F36: 1800W3-WFT-G2 AC100-240V 单开 | G36: 巴西527 | H36: 宜胜照明1 | L36: M2H036+M22H037-共16960ps开关，客户收到货发现玻璃脱落，且比例90%,客户库存5178pecs被封锁，导致客户无法供货给其零售商，造成10-12月销售损失，需赔3744美金，客诉描述此品质问题是由于生产端打胶未打好，导致玻璃大批脱落。 | M36: 16960 | N36: 5178 | O36: =IFERROR(N36/M36,"") -> 0.3053066 | P36: 售后客诉 | Q36: 内部 | R36: 胶水未打好，胶水没有完全固化干透进行组装，导致玻璃与面盖未贴牢。 | S36: 过程工艺 | T36: 需要我司免费提供5178pcs前面盖(玻璃+中框),并空运给客户 | U36: 1.壳体注塑工艺改良后续加强来料管控，整机配合检验；经确认现在来的物料无过紧的情况； 2.已与生产宣导，在组装安装时，如果有发现过紧的，需举手反馈给对应的线组长； 3. 打过胶后的半成品做好标识，时间记录好，确保胶水固化干的时间； 4.针对100PCS以下的尾数产品，线长贴尾数标识，送品质100%检验； 5.固化SOP，产线生产时，按照千分之五比例使用拉力器按照40N拉力进行检验； | V36: 否 | W36: 工艺优化 | X36: 宜胜照明1 | Y36: 生产一 | Z36: 45710 | AA36: 45710 | AB36: =IF(A36="","",_xlfn.IFS(AND(Z36=0,AA36=0),"未回复",AND(AA36<>0,Z36=0),"报错",AND(Z36>=NOW(),Z36<>0,AA36=0),"正常进行中",AND(AA36<>0,Z36>=AA36),"按时关闭",AND(Z36<>0,Z36<=AA36),"延期关闭",AND(AA36=0,Z36<NOW()),"延期未关闭")) -> 按时关闭 | AD36: =IF(Z36="","",YEAR(Z36)) -> 2025 | AE36: =IF(Z36="","",TEXT(Z36,"m")) -> 2 | AF36: =IF(Z36="","","W"&WEEKNUM(Z36,2)) -> W8
A37: 45712 | B37: =IF(A37="","",YEAR(A37)) -> 2025 | C37: =IF(A37="","",TEXT(A37,"m")) -> 2 | D37: =IF(A37="","","W"&WEEKNUM(A37,2)) -> W9 | E37: A122S108 | F37: LTI2711W4 -95W3-G1 | G37: 朗德万斯-巴西 | H37: 宜胜照明1 | L37: 客户反馈：我们面临最终客户索赔，在5月23日安装的154个灯具中，有88个LED HW T 100W 6500K（7019710），批次YS0123。 下面是更多细节： 它们是在安装过程中烧坏了还是同时出现了缺陷？他们是在这段时间烧坏了 灯具和屋顶之间的距离是多少？40厘米 该产品每天使用多少小时？24小时 灯具的电源电压是多少？220伏 灯具周围的环境温度~30℃ 电气装置是否用于连接中性线？这是有根据的吗？是的，它是接地的 电路中安装了多少个灯泡？每条电路22个 除了灯泡，这个电路中还有其他类型的负载吗？不 可以通过DHL向您发送6个样品进行技术分析吗？随附一些安装图片。 | M37: 1000 | N37: 88 | O37: =IFERROR(N37/M37,"") -> 0.088 | P37: 售后客诉 | Q37: 功能 | R37: 对不良样品进行拆机检验发现，侧线与灯头均有打火现象， 推测原因为侧线与灯头之间因接触不良而打火，瞬间电流过大，导致灯珠死灯；侧线与灯头接触不良原因：灯头为旋转灯头，侧线在装配过程未进行固定，灯头在旋转过程中侧线弯曲而进入螺纹间隙，导致接触不良，且此款灯泡功率100W，电流为457-800mA,本身运行过程功率与电流较大。 | S37: 过程工艺 | T37: 与客户沟通，对所有不良品进行补货赔偿处理，以减少客户损失，同时表达诚挚歉意。 | U37: 客户在本司所有大功率T灯采用切线工艺，如下图，侧线在装配过程中，先保证一部分线头露出灯头，待灯头压铆固定后，再将侧线露出灯头部分进行裁剪，保证侧线与灯头紧密接触，且灯头在装配过程中，侧线不会因旋转弯曲而产生间隙。 客户确认方案后，由产品端邮件通知生产进行SOP更新，后续LDWS大功率压铸铝T灯均采用切线工艺模式 | V37: 是 | W37: 防呆防错 | X37: 宜胜照明1 | Y37: 生产一 | Z37: 45713 | AA37: 45713 | AB37: =IF(A37="","",_xlfn.IFS(AND(Z37=0,AA37=0),"未回复",AND(AA37<>0,Z37=0),"报错",AND(Z37>=NOW(),Z37<>0,AA37=0),"正常进行中",AND(AA37<>0,Z37>=AA37),"按时关闭",AND(Z37<>0,Z37<=AA37),"延期关闭",AND(AA37=0,Z37<NOW()),"延期未关闭")) -> 按时关闭 | AD37: =IF(Z37="","",YEAR(Z37)) -> 2025 | AE37: =IF(Z37="","",TEXT(Z37,"m")) -> 2 | AF37: =IF(Z37="","","W"&WEEKNUM(Z37,2)) -> W9
A38: 45715 | B38: =IF(A38="","",YEAR(A38)) -> 2025 | C38: =IF(A38="","",TEXT(A38,"m")) -> 2 | D38: =IF(A38="","","W"&WEEKNUM(A38,2)) -> W9 | E38: S24J0821 | F38: 面壁开关 | G38: 阿根廷235 | H38: 宜胜照明1 | L38: 彩盒里发现其他PCB板子，彩盒有装错货现象 | M38: 17960 | O38: =IFERROR(N38/M38,"") -> 0 | P38: 售后客诉 | Q38: 包装 | R38: 1.物料标识管控不够细致，导致在包装过程彩盒中混入其他型号板子未被发现流出；彩盒装错货现象暂未手相关信息及图片 | S38: 人员作业 | V38: 否 | W38: 人员培训 | X38: 宜胜照明1 | Y38: 生产一 | Z38: 45716 | AA38: 45716 | AB38: =IF(A38="","",_xlfn.IFS(AND(Z38=0,AA38=0),"未回复",AND(AA38<>0,Z38=0),"报错",AND(Z38>=NOW(),Z38<>0,AA38=0),"正常进行中",AND(AA38<>0,Z38>=AA38),"按时关闭",AND(Z38<>0,Z38<=AA38),"延期关闭",AND(AA38=0,Z38<NOW()),"延期未关闭")) -> 按时关闭 | AD38: =IF(Z38="","",YEAR(Z38)) -> 2025 | AE38: =IF(Z38="","",TEXT(Z38,"m")) -> 2 | AF38: =IF(Z38="","","W"&WEEKNUM(Z38,2)) -> W9
A39: 45715 | B39: =IF(A39="","",YEAR(A39)) -> 2025 | C39: =IF(A39="","",TEXT(A39,"m")) -> 2 | D39: =IF(A39="","","W"&WEEKNUM(A39,2)) -> W9 | E39: Z24D042 | F39: LC2221W2-8W3-G1 | G39: 阿联酋689 | H39: 宜胜照明1 | L39: 10月份出货的灯杯，客户售卖出去使用一个月大量灭灯；现客户要求赔货25000只 | M39: 50000 | N39: 25000 | O39: =IFERROR(N39/M39,"") -> 0.5 | P39: 售后客诉 | Q39: 功能 | R39: 委外安富工厂经查是以下问题导致：1：端子松动引线掉落2：端子未焊接牢靠3：铆钉没有压到位 | S39: 过程工艺 | T39: 赔货处理 | U39: 1.针对灯头压铆不良，后续采取压铆两次，两面压铆，避免因压铆不良导致接触不良灯不亮得现象； 2.焊接工艺不良，此批次产品为委外供应商生产，后续对供应商选择，需要经过评估其生产工艺、质量体系是否符合公司标准，并定期进行审核；后续订单安排在宇兴宜胜进行生产。 | V39: 是 | W39: 其它 | X39: 计划采购部 | Y39: 供方管理组 | Z39: 45716 | AA39: 45716 | AB39: =IF(A39="","",_xlfn.IFS(AND(Z39=0,AA39=0),"未回复",AND(AA39<>0,Z39=0),"报错",AND(Z39>=NOW(),Z39<>0,AA39=0),"正常进行中",AND(AA39<>0,Z39>=AA39),"按时关闭",AND(Z39<>0,Z39<=AA39),"延期关闭",AND(AA39=0,Z39<NOW()),"延期未关闭")) -> 按时关闭 | AD39: =IF(Z39="","",YEAR(Z39)) -> 2025 | AE39: =IF(Z39="","",TEXT(Z39,"m")) -> 2 | AF39: =IF(Z39="","","W"&WEEKNUM(Z39,2)) -> W9
A40: 45715 | B40: =IF(A40="","",YEAR(A40)) -> 2025 | C40: =IF(A40="","",TEXT(A40,"m")) -> 2 | D40: =IF(A40="","","W"&WEEKNUM(A40,2)) -> W9 | E40: Z24D044 | F40: LC2221W2-8W3-G1 | G40: 阿联酋689 | H40: 宜胜照明1 | L40: 10月份出货的灯杯，客户售卖出去使用一个月大量灭灯；现客户要求赔货15000只 | M40: 30000 | N40: 15000 | O40: =IFERROR(N40/M40,"") -> 0.5 | P40: 售后客诉 | Q40: 功能 | R40: 委外安富工厂，经查是以下问题导致：1：端子松动引线掉落2：端子未焊接牢靠3：铆钉没有压到位 | S40: 过程工艺 | T40: 赔货处理 | U40: 1.针对灯头压铆不良，后续采取压铆两次，两面压铆，避免因压铆不良导致接触不良灯不亮得现象； 2.焊接工艺不良，此批次产品为委外供应商生产，后续对供应商选择，需要经过评估其生产工艺、质量体系是否符合公司标准，并定期进行审核；后续订单安排在宇兴宜胜进行生产。 | V40: 是 | W40: 其它 | X40: 计划采购部 | Y40: 供方管理组 | Z40: 45716 | AA40: 45716 | AB40: =IF(A40="","",_xlfn.IFS(AND(Z40=0,AA40=0),"未回复",AND(AA40<>0,Z40=0),"报错",AND(Z40>=NOW(),Z40<>0,AA40=0),"正常进行中",AND(AA40<>0,Z40>=AA40),"按时关闭",AND(Z40<>0,Z40<=AA40),"延期关闭",AND(AA40=0,Z40<NOW()),"延期未关闭")) -> 按时关闭 | AD40: =IF(Z40="","",YEAR(Z40)) -> 2025 | AE40: =IF(Z40="","",TEXT(Z40,"m")) -> 2 | AF40: =IF(Z40="","","W"&WEEKNUM(Z40,2)) -> W9
...

Sheet 宜胜客验台账 
A1: 发生时间 | B1: 年 | C1: 月 | D1: 周 | E1: 订单号 | F1: 产品型号 | G1: 客户 | H1: 事业部 | I1: 业务 | J1: 产品 | K1: CQE | L1: 问题描述 | M1: 问题来源 | N1: 问题类别 | O1: 原因分析 | P1: 原因类别 | Q1: 临时措施 | R1: 长期措施 | S1: 是否根本解 | T1: 措施类型 | U1: 责任部门 | V1: 二级部门3 | W1: 计划完成时间 | X1: 实际完成时间 | Y1: 状态 | Z1: 跟进人 | AA1: 计划完成年 | AB1: 计划完成月 | AC1: 计划完成周
A2: 45467 | B2: =IF(A2="","",YEAR(A2)) -> 2024 | C2: =IF(A2="","",TEXT(A2,"m")) -> 6 | D2: =IF(A2="","","W"&WEEKNUM(A2,2)) -> W26 | E2: M24H004-A | F2: ST-WS70071-1800W3-WFT-G2-单开-黑色 | G2: 巴西527 | H2: 宜胜照明1 | I2: 李佳思 | J2: 赖长金 | K2: 丁亚双 | L2: 客验中发现彩盒上有蓝色油印，不良比例31% | M2: 客户验货 | N2: 包装 | O2: 一、彩盒上有蓝色油印： 1.原因分析：天气潮湿原因，在生产过程中油墨未干，导致部分油墨擦花在在白色纸张上。 2、供应商在制作过程中因环境原因，导致不良流。 | P2: 来料不良 | Q2: 1、针对接到客户验货失败问题组织小组紧急处理，将对不良图片发到供应商，回复改善对策，并通知生产， 来料确认检验制度，针对供应商改善报告确认。 2、组织组长，主任以及生产工艺研讨此次验货失败的根本真因。 3、对于后续供应商彩盒改善跟进，针对后续来料彩盒检验规范，来料，制程 | R2: 1.供应商更改存放工艺。 2.针对供应商改善效果确认，及我司检验人员进行培训。 3.跟进供应商改善效果确认。 1、增加检验人员及生产人员培训外观质量标准，判定标准。 2、持续跟进我司对彩盒供应商评审，来料检验不良问题点记录，按月考察供应商。将问题跟供应商对接。 | S2: 否 | T2: 工艺优化 | U2: 计划采购部 | V2: 供方管理组 | W2: 45468 | X2: 45468 | Y2: =IF(A2="","",_xlfn.IFS(AND(W2=0,X2=0),"未回复",AND(X2<>0,W2=0),"报错",AND(W2>=NOW(),W2<>0,X2=0),"正常进行中",AND(X2<>0,W2>=X2),"按时关闭",AND(W2<>0,W2<=X2),"延期关闭",AND(X2=0,W2<NOW()),"延期未关闭")) -> 按时关闭 | Z2: 李俊林 | AA2: =IF(W2="","",YEAR(W2)) -> 2024 | AB2: =IF(W2="","",TEXT(W2,"m")) -> 6 | AC2: =IF(W2="","","W"&WEEKNUM(W2,2)) -> W26
A3: 45476 | B3: =IF(A3="","",YEAR(A3)) -> 2024 | C3: =IF(A3="","",TEXT(A3,"m")) -> 7 | D3: =IF(A3="","","W"&WEEKNUM(A3,2)) -> W27 | E3: M24H003/M24H009 | G3: 巴西527 | H3: 宜胜照明1 | I3: 李佳思 | J3: 赖长金 | K3: 丁亚双 | L3: 功能问题：1个插座功能紊乱； | M3: 客户验货 | N3: 功能 | O3: 测试时输出电压不稳定，打开发现输入电压位置虚焊导致 | P3: 人员作业 | Q3: 增加外观检验 | R3: 对该插座功能紊乱，增加自动焊锡机。替代人工焊接，提升焊接的质量 | S3: 是 | T3: 自动化 | U3: 宜胜照明1 | V3: 生产一 | W3: 45488 | Y3: =IF(A3="","",_xlfn.IFS(AND(W3=0,X3=0),"未回复",AND(X3<>0,W3=0),"报错",AND(W3>=NOW(),W3<>0,X3=0),"正常进行中",AND(X3<>0,W3>=X3),"按时关闭",AND(W3<>0,W3<=X3),"延期关闭",AND(X3=0,W3<NOW()),"延期未关闭")) -> 延期未关闭 | Z3: 李俊林 | AA3: =IF(W3="","",YEAR(W3)) -> 2024 | AB3: =IF(W3="","",TEXT(W3,"m")) -> 7 | AC3: =IF(W3="","","W"&WEEKNUM(W3,2)) -> W29
A4: 45476 | B4: =IF(A4="","",YEAR(A4)) -> 2024 | C4: =IF(A4="","",TEXT(A4,"m")) -> 7 | D4: =IF(A4="","","W"&WEEKNUM(A4,2)) -> W27 | E4: M24H003/M24H009 | G4: 巴西527 | H4: 宜胜照明1 | I4: 李佳思 | J4: 赖长金 | K4: 丁亚双 | L4: 功能问题：1个插座按键卡死 | M4: 客户验货 | N4: 功能 | O4: 经打开后发现PCB板上轻触按键歪与外壳按钮顶死 | P4: 过程工艺 | Q4: 插座按键死，增加人员在装配外壳后按键测试，不让不良品流出 | R4: 针对按键按不动，工艺增加工装，对开关按键进行焊接作业。防止开关按键歪斜 | S4: 是 | T4: 防呆防错 | U4: 宜胜照明1 | V4: 生产一 | W4: 45488 | Y4: =IF(A4="","",_xlfn.IFS(AND(W4=0,X4=0),"未回复",AND(X4<>0,W4=0),"报错",AND(W4>=NOW(),W4<>0,X4=0),"正常进行中",AND(X4<>0,W4>=X4),"按时关闭",AND(W4<>0,W4<=X4),"延期关闭",AND(X4=0,W4<NOW()),"延期未关闭")) -> 延期未关闭 | Z4: 李俊林 | AA4: =IF(W4="","",YEAR(W4)) -> 2024 | AB4: =IF(W4="","",TEXT(W4,"m")) -> 7 | AC4: =IF(W4="","","W"&WEEKNUM(W4,2)) -> W29
A5: 45476 | B5: =IF(A5="","",YEAR(A5)) -> 2024 | C5: =IF(A5="","",TEXT(A5,"m")) -> 7 | D5: =IF(A5="","","W"&WEEKNUM(A5,2)) -> W27 | E5: M24H003/M24H009 | G5: 巴西527 | H5: 宜胜照明1 | I5: 李佳思 | J5: 赖长金 | K5: 丁亚双 | L5: 外观问题： logo丝印倾斜，参数面丝印不居 | M5: 客户验货 | N5: 外观 | O5: logo丝印倾斜，参数面丝印不居:经确认发现打激光时，定位模具不精确 | P5: 过程工艺 | Q5: 修改定位模具 | R5: 激光打印歪斜：增加工装：1.一个打印LOGO面，利用LN针脚防止员工方向放错。2.一个治具的是产品要反过来，利用中间地针防止员工方向放错。 | S5: 是 | T5: 防呆防错 | U5: 宜胜照明1 | V5: 生产一 | W5: 45488 | Y5: =IF(A5="","",_xlfn.IFS(AND(W5=0,X5=0),"未回复",AND(X5<>0,W5=0),"报错",AND(W5>=NOW(),W5<>0,X5=0),"正常进行中",AND(X5<>0,W5>=X5),"按时关闭",AND(W5<>0,W5<=X5),"延期关闭",AND(X5=0,W5<NOW()),"延期未关闭")) -> 延期未关闭 | Z5: 李俊林 | AA5: =IF(W5="","",YEAR(W5)) -> 2024 | AB5: =IF(W5="","",TEXT(W5,"m")) -> 7 | AC5: =IF(W5="","","W"&WEEKNUM(W5,2)) -> W29
A6: 45475 | B6: =IF(A6="","",YEAR(A6)) -> 2024 | C6: =IF(A6="","",TEXT(A6,"m")) -> 7 | D6: =IF(A6="","","W"&WEEKNUM(A6,2)) -> W27 | E6: C24J0412- | F6: EL2206-10W | G6: 美国1024 | H6: 宜胜照明2 | I6: 罗倩倩 | J6: 史睿 | L6: 磁铁脱落 | M6: 客户验货 | N6: 功能 | O6: 生产时有发现磁铁掉落现象，磁铁牢固性SOP无明确要求，所以生产及检验未做检验，成品检验时也只抽检了几个 | P6: 结构设计 | Q6: 7月6号更改原返工方案磁铁吸力测试3次为测试10次，临时使用496瞬干胶进行返工 | R6: 1.黏磁铁胶水更改为8326结构胶，经验证双85高温高湿加破坏性试验取磁铁，牢固性OK | S6: 是 | T6: 设计变更-预防 | U6: 宜胜照明2 | W6: 45488 | X6: 45488 | Y6: =IF(A6="","",_xlfn.IFS(AND(W6=0,X6=0),"未回复",AND(X6<>0,W6=0),"报错",AND(W6>=NOW(),W6<>0,X6=0),"正常进行中",AND(X6<>0,W6>=X6),"按时关闭",AND(W6<>0,W6<=X6),"延期关闭",AND(X6=0,W6<NOW()),"延期未关闭")) -> 按时关闭 | Z6: 赵纯杰 | AA6: =IF(W6="","",YEAR(W6)) -> 2024 | AB6: =IF(W6="","",TEXT(W6,"m")) -> 7 | AC6: =IF(W6="","","W"&WEEKNUM(W6,2)) -> W29
A7: 45499 | B7: =IF(A7="","",YEAR(A7)) -> 2024 | C7: =IF(A7="","",TEXT(A7,"m")) -> 7 | D7: =IF(A7="","","W"&WEEKNUM(A7,2)) -> W30 | E7: A124R011-1 | F7: Z2-LG189-50W-RGB | G7: 中国907 | H7: 宜胜照明3 | I7: 傅利玮 | J7: 王燕赟 | K7: 王超 | L7: 抽验20PCS防水，发现2PCS产品内部出现流动的水珠 | M7: 客户验货 | N7: 功能 | O7: 壳体沙眼漏水，消耗老壳体库存，新结构壳体未发现漏水现象 | P7: 结构设计 | Q7: 泡水全检 | R7: 壳体结构已变更，老壳体沙眼问题无解决方案不得上线 | S7: 是 | T7: 设计变更-预防 | U7: 宜胜照明3 | V7: 生产三 | W7: 45502 | X7: 45502 | Y7: =IF(A7="","",_xlfn.IFS(AND(W7=0,X7=0),"未回复",AND(X7<>0,W7=0),"报错",AND(W7>=NOW(),W7<>0,X7=0),"正常进行中",AND(X7<>0,W7>=X7),"按时关闭",AND(W7<>0,W7<=X7),"延期关闭",AND(X7=0,W7<NOW()),"延期未关闭")) -> 按时关闭 | Z7: 赵纯杰 | AA7: =IF(W7="","",YEAR(W7)) -> 2024 | AB7: =IF(W7="","",TEXT(W7,"m")) -> 7 | AC7: =IF(W7="","","W"&WEEKNUM(W7,2)) -> W31
A8: 45499 | B8: =IF(A8="","",YEAR(A8)) -> 2024 | C8: =IF(A8="","",TEXT(A8,"m")) -> 7 | D8: =IF(A8="","","W"&WEEKNUM(A8,2)) -> W30 | E8: A124R011-1 | F8: Z2-LG189-50W-RGB | G8: 中国907 | H8: 宜胜照明3 | I8: 傅利玮 | J8: 王燕赟 | K8: 王超 | L8: 测试发现1PCS遥控失灵 | M8: 客户验货 | N8: 功能 | O8: 感应器信号接收异常 | P8: 过程工艺 | Q8: 遥控器一对一全检测试 | R8: 后续生产增加灯具与遥控器一对一测试 | S8: 否 | T8: 工艺优化 | U8: 宜胜照明3 | V8: 生产三 | W8: 45502 | X8: 45502 | Y8: =IF(A8="","",_xlfn.IFS(AND(W8=0,X8=0),"未回复",AND(X8<>0,W8=0),"报错",AND(W8>=NOW(),W8<>0,X8=0),"正常进行中",AND(X8<>0,W8>=X8),"按时关闭",AND(W8<>0,W8<=X8),"延期关闭",AND(X8=0,W8<NOW()),"延期未关闭")) -> 按时关闭 | Z8: 赵纯杰 | AA8: =IF(W8="","",YEAR(W8)) -> 2024 | AB8: =IF(W8="","",TEXT(W8,"m")) -> 7 | AC8: =IF(W8="","","W"&WEEKNUM(W8,2)) -> W31
A9: 45499 | B9: =IF(A9="","",YEAR(A9)) -> 2024 | C9: =IF(A9="","",TEXT(A9,"m")) -> 7 | D9: =IF(A9="","","W"&WEEKNUM(A9,2)) -> W30 | E9: A124R011-1 | F9: Z2-LG189-50W-RGB | G9: 中国907 | H9: 宜胜照明3 | I9: 傅利玮 | J9: 王燕赟 | K9: 王超 | L9: 产品彩盒LOG、彩盒底部二维码LOG与资料不一致，缺少LE，不良率100% | M9: 客户验货 | N9: 包装 | O9: 1.业务资料变更未通知 2.人员未核对出彩盒异常 | P9: 其它 | Q9: 超买标贴覆盖 | R9: 1.资料变更需走变更流程，并通知跟单、生产及品质 2.检验人员培训，漏检记入考核 | S9: 否 | T9: 纠错 | U9: 宜胜照明3 | V9: 研发一 | W9: 45502 | X9: 45502 | Y9: =IF(A9="","",_xlfn.IFS(AND(W9=0,X9=0),"未回复",AND(X9<>0,W9=0),"报错",AND(W9>=NOW(),W9<>0,X9=0),"正常进行中",AND(X9<>0,W9>=X9),"按时关闭",AND(W9<>0,W9<=X9),"延期关闭",AND(X9=0,W9<NOW()),"延期未关闭")) -> 按时关闭 | Z9: 赵纯杰 | AA9: =IF(W9="","",YEAR(W9)) -> 2024 | AB9: =IF(W9="","",TEXT(W9,"m")) -> 7 | AC9: =IF(W9="","","W"&WEEKNUM(W9,2)) -> W31
A10: 45499 | B10: =IF(A10="","",YEAR(A10)) -> 2024 | C10: =IF(A10="","",TEXT(A10,"m")) -> 7 | D10: =IF(A10="","","W"&WEEKNUM(A10,2)) -> W30 | E10: L24Y017/L24Y023 | G10: 墨西哥296 | K10: 丁亚双 | L10: 灯头底座有尖锐毛刺 1.25% 2. 产品有脏污 6.25% | M10: 客户验货 | N10: 外观 | Y10: =IF(A10="","",_xlfn.IFS(AND(W10=0,X10=0),"未回复",AND(X10<>0,W10=0),"报错",AND(W10>=NOW(),W10<>0,X10=0),"正常进行中",AND(X10<>0,W10>=X10),"按时关闭",AND(W10<>0,W10<=X10),"延期关闭",AND(X10=0,W10<NOW()),"延期未关闭")) -> 未回复 | Z10: 李俊林 | AA10: =IF(W10="","",YEAR(W10)) | AB10: =IF(W10="","",TEXT(W10,"m")) | AC10: =IF(W10="","","W"&WEEKNUM(W10,2))
A11: 45511 | B11: =IF(A11="","",YEAR(A11)) -> 2024 | C11: =IF(A11="","",TEXT(A11,"m")) -> 8 | D11: =IF(A11="","","W"&WEEKNUM(A11,2)) -> W32 | E11: M24H009 | F11: 插座 | G11: 巴西527 | H11: 宜胜照明1 | I11: 徐赢意 | J11: 赖长金 | K11: 丁亚双 | L11: 1.产品丝印不良。2.产品标签不良。3.6个彩盒标签方向反了。4.彩盒颜色不一致。 | M11: 客户验货 | N11: 外观 | O11: 1.外观不良： 1.产品丝印不良。2.产品标签不良。 3.6个彩盒标签方向反了。 4.彩盒颜色不一致。 1.产品丝印不良：生产作业人员补尾数打印时，未放平在定位模具里，就开始作业导致激光丝印不良。 2.产品标签不良：排查发现生产尾数时，因标签数量不够，使用机器打印，导致标签未覆膜，造成产品标签不良。 3.6个彩盒标签方向反了：经过确认为生产尾数时未经过流水线作业环节， 导致产品标签贴反。 4.彩盒颜色不一致：仓库物料排查，发现我司彩盒放置在仓库窗口边，导致阳光照射，出现颜色不一致。 | P11: 人员作业 | Q11: 1，针对外观不良的，进行返工。检查产品外观，功能测试。 2、彩盒颜色不一致，经过生产品质采购决定，此批彩盒全部进行更换处理，确保彩盒颜色一致性。 2、针对外观不良，返工发现8台，8台进行外壳更换。丝印不良返工未发现不良品 | R11: 1、生产人员进行培训，后续尾数进行管控处理。 2、针对后续尾数进行100%全检，生产检验完成，尾数报检品质进行100%全检。 3、针对尾数50-100之间，生产、品质进行100%全检。 | S11: 否 | T11: 人员培训 | U11: 宜胜照明1 | V11: 生产一 | W11: 45511 | X11: 45511 | Y11: =IF(A11="","",_xlfn.IFS(AND(W11=0,X11=0),"未回复",AND(X11<>0,W11=0),"报错",AND(W11>=NOW(),W11<>0,X11=0),"正常进行中",AND(X11<>0,W11>=X11),"按时关闭",AND(W11<>0,W11<=X11),"延期关闭",AND(X11=0,W11<NOW()),"延期未关闭")) -> 按时关闭 | Z11: 李俊林 | AA11: =IF(W11="","",YEAR(W11)) -> 2024 | AB11: =IF(W11="","",TEXT(W11,"m")) -> 8 | AC11: =IF(W11="","","W"&WEEKNUM(W11,2)) -> W32
A12: 45516 | B12: =IF(A12="","",YEAR(A12)) -> 2024 | C12: =IF(A12="","",TEXT(A12,"m")) -> 8 | D12: =IF(A12="","","W"&WEEKNUM(A12,2)) -> W33 | E12: P24I004 | F12: LG172L | G12: 俄罗斯1836 | H12: 宜胜照明3 | J12: 王燕赟 | K12: 刘晓慧 | L12: 客验测试IP65时 ，发现3PCS产品进水，分别为： 1.GPLF-30 1pc 小水珠 2.GTMS-60 1pc 三分之一圈未打胶 进水量大 3.GLS-100 1pc 小水珠 | M12: 客户验货 | N12: 功能 | O12: 1.固化夹子不够； 2.打胶设备调机 3.生产员工盖玻璃前未进行检查或检查不仔细； 4.换胶过程 5.胶水来料内部空气； 6.设备气压不稳定 | P12: 人员作业 | Q12: 1.热态泡水5-10S,产品需要全部浸末； 2.浸水后气枪将表面水吹干净后进行仔细检查 | R12: 1.增加固化使用夹子； 2.使用带增压棒的打胶设备（172） 3.打胶人员固定，上岗人员培训教育 4.打胶合玻璃后增加按压动作； 5.大货班组长需要自检防水，IPQC抽检防水 | S12: 是 | T12: 其它 | U12: 宜胜照明3 | V12: 生产三 | W12: 45520 | X12: 45520 | Y12: =IF(A12="","",_xlfn.IFS(AND(W12=0,X12=0),"未回复",AND(X12<>0,W12=0),"报错",AND(W12>=NOW(),W12<>0,X12=0),"正常进行中",AND(X12<>0,W12>=X12),"按时关闭",AND(W12<>0,W12<=X12),"延期关闭",AND(X12=0,W12<NOW()),"延期未关闭")) -> 按时关闭 | Z12: 赵纯杰 | AA12: =IF(W12="","",YEAR(W12)) -> 2024 | AB12: =IF(W12="","",TEXT(W12,"m")) -> 8 | AC12: =IF(W12="","","W"&WEEKNUM(W12,2)) -> W33
A13: 45517 | B13: =IF(A13="","",YEAR(A13)) -> 2024 | C13: =IF(A13="","",TEXT(A13,"m")) -> 8 | D13: =IF(A13="","","W"&WEEKNUM(A13,2)) -> W33 | E13: R24X0517-1 | F13: RL160C-150W | G13: 俄罗斯745 | H13: 宜胜照明3 | J13: 陈中平协助 | K13: 李冬雪 | L13: 低温-40度启动不过，出现闪灯现象 | M13: 客户验货 | N13: 功能 | O13: 按研发方案R5改成51010200300 RES-SMD-1206-160K-5%-0.25W 两个电解电容改成51020400749 电容-电解电容 330uF-80V-10x25-105°-6KH-脚长3.5 云睿 ，经验证-40℃低温测试合格，无闪灯现象 | P13: 电子设计 | Q13: 按验证方案返工 | R13: 按验证方案更改电子设计 | S13: 是 | T13: 设计变更-预防 | U13: 宜胜照明3 | V13: 研发一 | W13: 45524 | X13: 45524 | Y13: =IF(A13="","",_xlfn.IFS(AND(W13=0,X13=0),"未回复",AND(X13<>0,W13=0),"报错",AND(W13>=NOW(),W13<>0,X13=0),"正常进行中",AND(X13<>0,W13>=X13),"按时关闭",AND(W13<>0,W13<=X13),"延期关闭",AND(X13=0,W13<NOW()),"延期未关闭")) -> 按时关闭 | AA13: =IF(W13="","",YEAR(W13)) -> 2024 | AB13: =IF(W13="","",TEXT(W13,"m")) -> 8 | AC13: =IF(W13="","","W"&WEEKNUM(W13,2)) -> W34
A14: 45495 | B14: =IF(A14="","",YEAR(A14)) -> 2024 | C14: =IF(A14="","",TEXT(A14,"m")) -> 7 | D14: =IF(A14="","","W"&WEEKNUM(A14,2)) -> W30 | E14: Y24K014-1 | F14: CE3030_30W | G14: 10030300028 | H14: 宜胜照明2 | J14: 杜捷 | L14: 浪涌测L-N 1KV不过，500V也不过，研发、业务沟通先客验，客验不合格 | M14: 客户验货 | N14: 功能 | O14: 设计原因 | P14: 电子设计 | Q14: 返工成本较高，需要10元/pcs,暂无其他解决方案 | Y14: =IF(A14="","",_xlfn.IFS(AND(W14=0,X14=0),"未回复",AND(X14<>0,W14=0),"报错",AND(W14>=NOW(),W14<>0,X14=0),"正常进行中",AND(X14<>0,W14>=X14),"按时关闭",AND(W14<>0,W14<=X14),"延期关闭",AND(X14=0,W14<NOW()),"延期未关闭")) -> 未回复 | AA14: =IF(W14="","",YEAR(W14)) | AB14: =IF(W14="","",TEXT(W14,"m")) | AC14: =IF(W14="","","W"&WEEKNUM(W14,2))
A15: 45525 | B15: =IF(A15="","",YEAR(A15)) -> 2024 | C15: =IF(A15="","",TEXT(A15,"m")) -> 8 | D15: =IF(A15="","","W"&WEEKNUM(A15,2)) -> W34 | E15: A124S048 | F15: 球泡 | G15: 郎德万斯-俄罗斯 | H15: 宜胜照明1 | I15: 张美娟 | L15: 外箱LOGO 工艺单是不需要印刷的 、客户验货发现 | M15: 客户验货 | N15: 外观 | O15: 经过调查发现，7/19号来料外箱与工艺单不符，此工单外箱IQC检验，已经发现问题，并通知采购进行处理，并通知仓库进行退货处理。已做好不良标识，生产时，仓库将不良外箱发放生产使用，未将重新购买外箱发放。生产作业时，未检验出，导致生产错误，FQC验货未发现，导致货物流出。 | P15: 来料不良 | Q15: 更换外箱 | S15: 否 | T15: 纠错 | U15: 其它事业部 | W15: 45519 | X15: 45527 | Y15: =IF(A15="","",_xlfn.IFS(AND(W15=0,X15=0),"未回复",AND(X15<>0,W15=0),"报错",AND(W15>=NOW(),W15<>0,X15=0),"正常进行中",AND(X15<>0,W15>=X15),"按时关闭",AND(W15<>0,W15<=X15),"延期关闭",AND(X15=0,W15<NOW()),"延期未关闭")) -> 延期关闭 | AA15: =IF(W15="","",YEAR(W15)) -> 2024 | AB15: =IF(W15="","",TEXT(W15,"m")) -> 8 | AC15: =IF(W15="","","W"&WEEKNUM(W15,2)) -> W33
A16: 45527 | B16: =IF(A16="","",YEAR(A16)) -> 2024 | C16: =IF(A16="","",TEXT(A16,"m")) -> 8 | D16: =IF(A16="","","W"&WEEKNUM(A16,2)) -> W34 | E16: O24B009-1 | F16: 路灯_RL160C-50W | G16: 瑞典176 | H16: 宜胜照明3 | I16: 徐陈艳 | J16: 余元浩 | K16: 李宁 | L16: 打耐压后灯不亮，客户拆机发现，内部合压端子头有漏铜线现象，要求全检返工 | M16: 客户验货 | N16: 安规 | O16: 员工操作不当，压端子压合不良 | P16: 人员作业 | Q16: 全检返工 | Y16: =IF(A16="","",_xlfn.IFS(AND(W16=0,X16=0),"未回复",AND(X16<>0,W16=0),"报错",AND(W16>=NOW(),W16<>0,X16=0),"正常进行中",AND(X16<>0,W16>=X16),"按时关闭",AND(W16<>0,W16<=X16),"延期关闭",AND(X16=0,W16<NOW()),"延期未关闭")) -> 未回复 | AA16: =IF(W16="","",YEAR(W16)) | AB16: =IF(W16="","",TEXT(W16,"m")) | AC16: =IF(W16="","","W"&WEEKNUM(W16,2))
A17: 45540 | B17: =IF(A17="","",YEAR(A17)) -> 2024 | C17: =IF(A17="","",TEXT(A17,"m")) -> 9 | D17: =IF(A17="","","W"&WEEKNUM(A17,2)) -> W36 | E17: A24C005-2 | F17: LG168C-50W 10010400208 | G17: 菲律宾429 | H17: 宜胜照明3 | J17: 王燕赟 | K17: 施奉勇 | L17: 客验时发现灯体表面壳体缝隙，冲水后有漏水现象（毛胚料号： 58010100064宝韵） | M17: 客户验货 | N17: 功能 | O17: 壳体变形导致漏水 | P17: 来料不良 | Q17: 全检返工 | R17: 1.物料来料把控变形严重需判不合格 2.订单生产时确认缝隙大小 如缝隙有单不大 胶水打厚确认玻璃与主体粘结密封 订单继续生产 缝隙大的产品 主体退不良 3.针对该问题车间培训 问题点横向展开避免问题点重复发生 | S17: 否 | T17: 纠错 | U17: 计划采购部 | V17: 供方管理组 | W17: 45541 | X17: 45541 | Y17: =IF(A17="","",_xlfn.IFS(AND(W17=0,X17=0),"未回复",AND(X17<>0,W17=0),"报错",AND(W17>=NOW(),W17<>0,X17=0),"正常进行中",AND(X17<>0,W17>=X17),"按时关闭",AND(W17<>0,W17<=X17),"延期关闭",AND(X17=0,W17<NOW()),"延期未关闭")) -> 按时关闭 | AA17: =IF(W17="","",YEAR(W17)) -> 2024 | AB17: =IF(W17="","",TEXT(W17,"m")) -> 9 | AC17: =IF(W17="","","W"&WEEKNUM(W17,2)) -> W36
A18: 45545 | B18: =IF(A18="","",YEAR(A18)) -> 2024 | C18: =IF(A18="","",TEXT(A18,"m")) -> 9 | D18: =IF(A18="","","W"&WEEKNUM(A18,2)) -> W37 | E18: M24W028-3 | F18: LG189L-200W | G18: 阿根廷215 | H18: 宜胜照明3 | J18: 王燕赟 | L18: 彩盒漏印产品LOGO，不良比例100% | M18: 客户验货 | N18: 包装 | O18: 来料漏印刷、漏检 | P18: 来料不良 | Q18: 返工更换彩盒 | R18: 1.IPQC人员检验流程培训 2.来料加强检验 | S18: 否 | T18: 纠错 | U18: 计划采购部 | V18: 供方管理组 | W18: 45550 | Y18: =IF(A18="","",_xlfn.IFS(AND(W18=0,X18=0),"未回复",AND(X18<>0,W18=0),"报错",AND(W18>=NOW(),W18<>0,X18=0),"正常进行中",AND(X18<>0,W18>=X18),"按时关闭",AND(W18<>0,W18<=X18),"延期关闭",AND(X18=0,W18<NOW()),"延期未关闭")) -> 延期未关闭 | AA18: =IF(W18="","",YEAR(W18)) -> 2024 | AB18: =IF(W18="","",TEXT(W18,"m")) -> 9 | AC18: =IF(W18="","","W"&WEEKNUM(W18,2)) -> W37
A19: 45547 | B19: =IF(A19="","",YEAR(A19)) -> 2024 | C19: =IF(A19="","",TEXT(A19,"m")) -> 9 | D19: =IF(A19="","","W"&WEEKNUM(A19,2)) -> W37 | E19: A124R011 | F19: Z2-LG189-15W-RGB | G19: 中国907 | H19: 宜胜照明3 | J19: 王燕赟 | K19: 王超 | L19: 1PCS遥控失灵 | M19: 客户验货 | N19: 功能 | O19: 三极管虚焊 | P19: 过程工艺 | Q19: 全检返工 | R19: 为之前尾数，目前所有产品已经进行遥控一对一测试 | S19: 否 | T19: 纠错 | U19: 宜胜照明3 | V19: 生产三 | W19: 45547 | X19: 45547 | Y19: =IF(A19="","",_xlfn.IFS(AND(W19=0,X19=0),"未回复",AND(X19<>0,W19=0),"报错",AND(W19>=NOW(),W19<>0,X19=0),"正常进行中",AND(X19<>0,W19>=X19),"按时关闭",AND(W19<>0,W19<=X19),"延期关闭",AND(X19=0,W19<NOW()),"延期未关闭")) -> 按时关闭 | AA19: =IF(W19="","",YEAR(W19)) -> 2024 | AB19: =IF(W19="","",TEXT(W19,"m")) -> 9 | AC19: =IF(W19="","","W"&WEEKNUM(W19,2)) -> W37
A20: 45547 | B20: =IF(A20="","",YEAR(A20)) -> 2024 | C20: =IF(A20="","",TEXT(A20,"m")) -> 9 | D20: =IF(A20="","","W"&WEEKNUM(A20,2)) -> W37 | E20: A124R011 | F20: 10W/20W/15W/50W | G20: 中国907 | H20: 宜胜照明3 | J20: 王燕赟 | K20: 王超 | L20: 测试防水IP65后老化1小时，发现灯体玻璃内出现可移动水珠 | M20: 客户验货 | N20: 内部 | O20: 灯体密封，内外温差形成水汽 | P20: 结构设计 | R20: 暂无解决方案 | Y20: =IF(A20="","",_xlfn.IFS(AND(W20=0,X20=0),"未回复",AND(X20<>0,W20=0),"报错",AND(W20>=NOW(),W20<>0,X20=0),"正常进行中",AND(X20<>0,W20>=X20),"按时关闭",AND(W20<>0,W20<=X20),"延期关闭",AND(X20=0,W20<NOW()),"延期未关闭")) -> 未回复 | AA20: =IF(W20="","",YEAR(W20)) | AB20: =IF(W20="","",TEXT(W20,"m")) | AC20: =IF(W20="","","W"&WEEKNUM(W20,2))
A21: 45547 | B21: =IF(A21="","",YEAR(A21)) -> 2024 | C21: =IF(A21="","",TEXT(A21,"m")) -> 9 | D21: =IF(A21="","","W"&WEEKNUM(A21,2)) -> W37 | E21: A124R021 | F21: 10W/50W | G21: 中国907 | H21: 宜胜照明3 | J21: 王燕赟 | K21: 王超 | L21: 测试防水IP65后老化1小时，发现灯体玻璃内出现可移动水珠 | M21: 客户验货 | N21: 内部 | O21: 灯体密封，内外温差形成水汽 | P21: 结构设计 | R21: 暂无解决方案 | Y21: =IF(A21="","",_xlfn.IFS(AND(W21=0,X21=0),"未回复",AND(X21<>0,W21=0),"报错",AND(W21>=NOW(),W21<>0,X21=0),"正常进行中",AND(X21<>0,W21>=X21),"按时关闭",AND(W21<>0,W21<=X21),"延期关闭",AND(X21=0,W21<NOW()),"延期未关闭")) -> 未回复 | AA21: =IF(W21="","",YEAR(W21)) | AB21: =IF(W21="","",TEXT(W21,"m")) | AC21: =IF(W21="","","W"&WEEKNUM(W21,2))
A22: 45547 | B22: =IF(A22="","",YEAR(A22)) -> 2024 | C22: =IF(A22="","",TEXT(A22,"m")) -> 9 | D22: =IF(A22="","","W"&WEEKNUM(A22,2)) -> W37 | E22: A124R021 | F22: 10W感应款 | G22: 中国907 | H22: 宜胜照明3 | J22: 王燕赟 | K22: 王超 | L22: 1PCS彩盒标贴漏贴 | M22: 客户验货 | N22: 包装 | O22: 员工漏贴 | P22: 人员作业 | Q22: 全检返工 | R22: 1.增加包装首件放置于包装线 2.生产前对标贴人员、外观人员进行培训 3.加强员工质量意识 | S22: 否 | T22: 人员培训 | U22: 宜胜照明3 | V22: 生产三 | W22: 45563 | X22: 45563 | Y22: =IF(A22="","",_xlfn.IFS(AND(W22=0,X22=0),"未回复",AND(X22<>0,W22=0),"报错",AND(W22>=NOW(),W22<>0,X22=0),"正常进行中",AND(X22<>0,W22>=X22),"按时关闭",AND(W22<>0,W22<=X22),"延期关闭",AND(X22=0,W22<NOW()),"延期未关闭")) -> 按时关闭 | AA22: =IF(W22="","",YEAR(W22)) -> 2024 | AB22: =IF(W22="","",TEXT(W22,"m")) -> 9 | AC22: =IF(W22="","","W"&WEEKNUM(W22,2)) -> W39
A23: 45558 | B23: =IF(A23="","",YEAR(A23)) -> 2024 | C23: =IF(A23="","",TEXT(A23,"m")) -> 9 | D23: =IF(A23="","","W"&WEEKNUM(A23,2)) -> W39 | E23: P24V002-1 | F23: LG172L-50W/100W | G23: 俄罗斯482 | H23: 宜胜照明3 | J23: 王燕赟 | L23: 防水不过50W、100W各1pcs | M23: 客户验货 | N23: 功能 | O23: 经拆灯发现为进线口打胶未打好 | P23: 人员作业 | R23: 产品个例 初步判定为自动线停止运行胶干 流动性达不到 重新运行后前几个产品胶水可能未打到位 整改措施为每天上班前胶水先放胶一分钟 确认无问题再开始生产 休息时间重新启动也同样检查胶水无问题开始生产 | S23: 否 | T23: 人员培训 | U23: 宜胜照明3 | V23: 生产三 | W23: 45563 | X23: 45563 | Y23: =IF(A23="","",_xlfn.IFS(AND(W23=0,X23=0),"未回复",AND(X23<>0,W23=0),"报错",AND(W23>=NOW(),W23<>0,X23=0),"正常进行中",AND(X23<>0,W23>=X23),"按时关闭",AND(W23<>0,W23<=X23),"延期关闭",AND(X23=0,W23<NOW()),"延期未关闭")) -> 按时关闭 | AA23: =IF(W23="","",YEAR(W23)) -> 2024 | AB23: =IF(W23="","",TEXT(W23,"m")) -> 9 | AC23: =IF(W23="","","W"&WEEKNUM(W23,2)) -> W39
